Workbook

Sheet Tech Graph
A1: Date | B1: Intellectualists | C1: Clerks | D1: Literacy | E1: Status | F1: Base Research Points | G1: Plurality | H1: Tech Modifier | I1: Total Research Points | J1: Yearly Research Points | K1: New Costs | L1: Date | M1: Leftover Tech Cost
A2: 1830 | B2: 0.0098 | C2: 0.0041 | D2: 0.1 | E2: Great Power | F2: =(MIN(B2,0.02)*150)+(MIN(C2,0.04)*50)+(MIN(D2,1)*4)+(IF(E2="Great Power",1.5,IF(E2="Secondary Power",1.25,IF(E2="Westernized Nation",1,0)))) -> 3.575 | G2: 0.3 | H2: 0 | I2: =F2*(1+H2+G2) -> 4.6475 | J2: =I2*365 -> 1696.3375 | K2: 244800 | L2: 1830 | M2: =MAX(K2-J2,0) -> 243103.66
A3: 1831 | B3: 0.01 | C3: 0.0043 | D3: 0.10171429 | E3: Great Power | F3: =(MIN(B3,0.02)*150)+(MIN(C3,0.04)*50)+(MIN(D3,1)*4)+(IF(E3="Great Power",1.5,IF(E3="Secondary Power",1.25,IF(E3="Westernized Nation",1,0)))) -> 3.6218571 | G3: =MIN(G2+(4*2/90/100*12),1) -> 0.31066667 | H3: 0 | I3: =F3*(1+H3+G3) -> 4.7470474 | J3: =I3*365 -> 1732.6723 | L3: 1831 | M3: =MAX((M2+K3-J3)*0.994,0) -> 239922.76
A4: 1832 | B4: 0.0108 | C4: 0.0045 | D4: 0.1036 | E4: Great Power | F4: =(MIN(B4,0.02)*150)+(MIN(C4,0.04)*50)+(MIN(D4,1)*4)+(IF(E4="Great Power",1.5,IF(E4="Secondary Power",1.25,IF(E4="Westernized Nation",1,0)))) -> 3.7594 | G4: =MIN(G3+(4*2/90/100*12),1) -> 0.32133333 | H4: 0 | I4: =F4*(1+H4+G4) -> 4.9674205 | J4: =I4*365 -> 1813.1085 | L4: 1832 | M4: =MAX((M3+K4-J4)*0.994,0) -> 236681
A5: 1833 | B5: 0.0116 | C5: 0.0047 | D5: 0.10565714 | E5: Great Power | F5: =(MIN(B5,0.02)*150)+(MIN(C5,0.04)*50)+(MIN(D5,1)*4)+(IF(E5="Great Power",1.5,IF(E5="Secondary Power",1.25,IF(E5="Westernized Nation",1,0)))) -> 3.8976286 | G5: =MIN(G4+(4*2/90/100*12),1) -> 0.332 | H5: 0 | I5: =F5*(1+H5+G5) -> 5.1916413 | J5: =I5*365 -> 1894.9491 | L5: 1833 | M5: =MAX((M4+K5-J5)*0.994,0) -> 233377.33
A6: 1834 | B6: 0.0124 | C6: 0.0049 | D6: 0.10788571 | E6: Great Power | F6: =(MIN(B6,0.02)*150)+(MIN(C6,0.04)*50)+(MIN(D6,1)*4)+(IF(E6="Great Power",1.5,IF(E6="Secondary Power",1.25,IF(E6="Westernized Nation",1,0)))) -> 4.0365429 | G6: =MIN(G5+(4*2/90/100*12),1) -> 0.34266667 | H6: 0 | I6: =F6*(1+H6+G6) -> 5.4197315 | J6: =I6*365 -> 1978.202 | L6: 1834 | M6: =MAX((M5+K6-J6)*0.994,0) -> 230010.74
A7: 1835 | B7: 0.0132 | C7: 0.0051 | D7: 0.11028571 | E7: Great Power | F7: =(MIN(B7,0.02)*150)+(MIN(C7,0.04)*50)+(MIN(D7,1)*4)+(IF(E7="Great Power",1.5,IF(E7="Secondary Power",1.25,IF(E7="Westernized Nation",1,0)))) -> 4.1761429 | G7: =MIN(G6+(4*2/90/100*12),1) -> 0.35333333 | H7: 0 | I7: =F7*(1+H7+G7) -> 5.6517133 | J7: =I7*365 -> 2062.8754 | L7: 1835 | M7: =MAX((M6+K7-J7)*0.994,0) -> 226580.17
A8: 1836 | B8: 0.014 | C8: 0.0053 | D8: 0.11285714 | E8: Great Power | F8: =(MIN(B8,0.02)*150)+(MIN(C8,0.04)*50)+(MIN(D8,1)*4)+(IF(E8="Great Power",1.5,IF(E8="Secondary Power",1.25,IF(E8="Westernized Nation",1,0)))) -> 4.3164286 | G8: =MIN(G7+(4*2/90/100*12),1) -> 0.364 | H8: 0 | I8: =F8*(1+H8+G8) -> 5.8876086 | J8: =I8*365 -> 2148.9771 | L8: 1836 | M8: =MAX((M7+K8-J8)*0.994,0) -> 223084.61
A9: 1837 | B9: 0.0148 | C9: 0.0055 | D9: 0.1156 | E9: Great Power | F9: =(MIN(B9,0.02)*150)+(MIN(C9,0.04)*50)+(MIN(D9,1)*4)+(IF(E9="Great Power",1.5,IF(E9="Secondary Power",1.25,IF(E9="Westernized Nation",1,0)))) -> 4.4574 | G9: =MIN(G8+(4*2/90/100*12),1) -> 0.37466667 | H9: 0 | I9: =F9*(1+H9+G9) -> 6.1274392 | J9: =I9*365 -> 2236.5153 | L9: 1837 | M9: =MAX((M8+K9-J9)*0.994,0) -> 219523
A10: 1838 | B10: 0.0156 | C10: 0.0057 | D10: 0.11851429 | E10: Great Power | F10: =(MIN(B10,0.02)*150)+(MIN(C10,0.04)*50)+(MIN(D10,1)*4)+(IF(E10="Great Power",1.5,IF(E10="Secondary Power",1.25,IF(E10="Westernized Nation",1,0)))) -> 4.5990571 | G10: =MIN(G9+(4*2/90/100*12),1) -> 0.38533333 | H10: 0 | I10: =F10*(1+H10+G10) -> 6.3712272 | J10: =I10*365 -> 2325.4979 | L10: 1838 | M10: =MAX((M9+K10-J10)*0.994,0) -> 215894.32
A11: 1839 | B11: 0.0164 | C11: 0.0059 | D11: 0.1216 | E11: Great Power | F11: =(MIN(B11,0.02)*150)+(MIN(C11,0.04)*50)+(MIN(D11,1)*4)+(IF(E11="Great Power",1.5,IF(E11="Secondary Power",1.25,IF(E11="Westernized Nation",1,0)))) -> 4.7414 | G11: =MIN(G10+(4*2/90/100*12),1) -> 0.396 | H11: 0 | I11: =F11*(1+H11+G11) -> 6.6189944 | J11: =I11*365 -> 2415.933 | L11: 1839 | M11: =MAX((M10+K11-J11)*0.994,0) -> 212197.52
A12: 1840 | B12: 0.0172 | C12: 0.0061 | D12: 0.12485714 | E12: Great Power | F12: =(MIN(B12,0.02)*150)+(MIN(C12,0.04)*50)+(MIN(D12,1)*4)+(IF(E12="Great Power",1.5,IF(E12="Secondary Power",1.25,IF(E12="Westernized Nation",1,0)))) -> 4.8844286 | G12: =MIN(G11+(4*2/90/100*12),1) -> 0.40666667 | H12: 0.5 | I12: =F12*(1+H12+G12) -> 9.3129771 | J12: =I12*365 -> 3399.2367 | K12: 32400 | L12: 1840 | M12: =MAX((M11+K12-J12)*0.994,0) -> 239751.09
A13: 1841 | B13: 0.018 | C13: 0.0063 | D13: 0.12828571 | E13: Great Power | F13: =(MIN(B13,0.02)*150)+(MIN(C13,0.04)*50)+(MIN(D13,1)*4)+(IF(E13="Great Power",1.5,IF(E13="Secondary Power",1.25,IF(E13="Westernized Nation",1,0)))) -> 5.0281429 | G13: =MIN(G12+(4*2/90/100*12),1) -> 0.41733333 | H13: 0.5 | I13: =F13*(1+H13+G13) -> 9.6406259 | J13: =I13*365 -> 3518.8285 | L13: 1841 | M13: =MAX((M12+K13-J13)*0.994,0) -> 234814.87
A14: 1842 | B14: 0.0188 | C14: 0.0065 | D14: 0.13188571 | E14: Great Power | F14: =(MIN(B14,0.02)*150)+(MIN(C14,0.04)*50)+(MIN(D14,1)*4)+(IF(E14="Great Power",1.5,IF(E14="Secondary Power",1.25,IF(E14="Westernized Nation",1,0)))) -> 5.1725429 | G14: =MIN(G13+(4*2/90/100*12),1) -> 0.428 | H14: 0.5 | I14: =F14*(1+H14+G14) -> 9.9726626 | J14: =I14*365 -> 3640.0219 | L14: 1842 | M14: =MAX((M13+K14-J14)*0.994,0) -> 229787.8
A15: 1843 | B15: 0.0196 | C15: 0.0067 | D15: 0.13565714 | E15: Great Power | F15: =(MIN(B15,0.02)*150)+(MIN(C15,0.04)*50)+(MIN(D15,1)*4)+(IF(E15="Great Power",1.5,IF(E15="Secondary Power",1.25,IF(E15="Westernized Nation",1,0)))) -> 5.3176286 | G15: =MIN(G14+(4*2/90/100*12),1) -> 0.43866667 | H15: 1 | I15: =F15*(1+H15+G15) -> 12.967924 | J15: =I15*365 -> 4733.2921 | L15: 1843 | M15: =MAX((M14+K15-J15)*0.994,0) -> 223704.18
A16: 1844 | B16: 0.0204 | C16: 0.0069 | D16: 0.139876 | E16: Great Power | F16: =(MIN(B16,0.02)*150)+(MIN(C16,0.04)*50)+(MIN(D16,1)*4)+(IF(E16="Great Power",1.5,IF(E16="Secondary Power",1.25,IF(E16="Westernized Nation",1,0)))) -> 5.404504 | G16: =MIN(G15+(4*2/90/100*12),1) -> 0.44933333 | H16: 1 | I16: =F16*(1+H16+G16) -> 13.237432 | J16: =I16*365 -> 4831.6626 | L16: 1844 | M16: =MAX((M15+K16-J16)*0.994,0) -> 217559.28
A17: 1845 | B17: 0.0212 | C17: 0.0071 | D17: 0.14468971 | E17: Great Power | F17: =(MIN(B17,0.02)*150)+(MIN(C17,0.04)*50)+(MIN(D17,1)*4)+(IF(E17="Great Power",1.5,IF(E17="Secondary Power",1.25,IF(E17="Westernized Nation",1,0)))) -> 5.4337589 | G17: =MIN(G16+(4*2/90/100*12),1) -> 0.46 | H17: 1 | I17: =F17*(1+H17+G17) -> 13.367047 | J17: =I17*365 -> 4878.9721 | L17: 1845 | M17: =MAX((M16+K17-J17)*0.994,0) -> 211404.23
A18: 1846 | B18: 0.022 | C18: 0.0073 | D18: 0.149704 | E18: Great Power | F18: =(MIN(B18,0.02)*150)+(MIN(C18,0.04)*50)+(MIN(D18,1)*4)+(IF(E18="Great Power",1.5,IF(E18="Secondary Power",1.25,IF(E18="Westernized Nation",1,0)))) -> 5.463816 | G18: =MIN(G17+(4*2/90/100*12),1) -> 0.47066667 | H18: 1 | I18: =F18*(1+H18+G18) -> 13.499268 | J18: =I18*365 -> 4927.2328 | L18: 1846 | M18: =MAX((M17+K18-J18)*0.994,0) -> 205238.13
A19: 1847 | B19: 0.0228 | C19: 0.0075 | D19: 0.15491886 | E19: Great Power | F19: =(MIN(B19,0.02)*150)+(MIN(C19,0.04)*50)+(MIN(D19,1)*4)+(IF(E19="Great Power",1.5,IF(E19="Secondary Power",1.25,IF(E19="Westernized Nation",1,0)))) -> 5.4946754 | G19: =MIN(G18+(4*2/90/100*12),1) -> 0.48133333 | H19: 1 | I19: =F19*(1+H19+G19) -> 13.634121 | J19: =I19*365 -> 4976.4543 | L19: 1847 | M19: =MAX((M18+K19-J19)*0.994,0) -> 199060.11
A20: 1848 | B20: 0.0236 | C20: 0.0077 | D20: 0.16033429 | E20: Great Power | F20: =(MIN(B20,0.02)*150)+(MIN(C20,0.04)*50)+(MIN(D20,1)*4)+(IF(E20="Great Power",1.5,IF(E20="Secondary Power",1.25,IF(E20="Westernized Nation",1,0)))) -> 5.5263371 | G20: =MIN(G19+(4*2/90/100*12),1) -> 0.492 | H20: 1 | I20: =F20*(1+H20+G20) -> 13.771632 | J20: =I20*365 -> 5026.6457 | K20: 10800 | L20: 1848 | M20: =MAX((M19+K20-J20)*0.994,0) -> 203604.46
A21: 1849 | B21: 0.0244 | C21: 0.0079 | D21: 0.16595029 | E21: Great Power | F21: =(MIN(B21,0.02)*150)+(MIN(C21,0.04)*50)+(MIN(D21,1)*4)+(IF(E21="Great Power",1.5,IF(E21="Secondary Power",1.25,IF(E21="Westernized Nation",1,0)))) -> 5.5588011 | G21: =MIN(G20+(4*2/90/100*12),1) -> 0.50266667 | H21: 1 | I21: =F21*(1+H21+G21) -> 13.911826 | J21: =I21*365 -> 5077.8166 | L21: 1849 | M21: =MAX((M20+K21-J21)*0.994,0) -> 197335.49
A22: 1850 | B22: 0.0252 | C22: 0.0081 | D22: 0.17176686 | E22: Great Power | F22: =(MIN(B22,0.02)*150)+(MIN(C22,0.04)*50)+(MIN(D22,1)*4)+(IF(E22="Great Power",1.5,IF(E22="Secondary Power",1.25,IF(E22="Westernized Nation",1,0)))) -> 5.5920674 | G22: =MIN(G21+(4*2/90/100*12),1) -> 0.51333333 | H22: 1 | I22: =F22*(1+H22+G22) -> 14.054729 | J22: =I22*365 -> 5129.9763 | K22: 259200 | L22: 1850 | M22: =MAX((M21+K22-J22)*0.994,0) -> 448697.08
A23: 1851 | B23: 0.026 | C23: 0.0083 | D23: 0.177784 | E23: Great Power | F23: =(MIN(B23,0.02)*150)+(MIN(C23,0.04)*50)+(MIN(D23,1)*4)+(IF(E23="Great Power",1.5,IF(E23="Secondary Power",1.25,IF(E23="Westernized Nation",1,0)))) -> 5.626136 | G23: =MIN(G22+(4*2/90/100*12),1) -> 0.524 | H23: 1 | I23: =F23*(1+H23+G23) -> 14.200367 | J23: =I23*365 -> 5183.1341 | L23: 1851 | M23: =MAX((M22+K23-J23)*0.994,0) -> 440852.86
A24: 1852 | B24: 0.0268 | C24: 0.0085 | D24: 0.18453314 | E24: Great Power | F24: =(MIN(B24,0.02)*150)+(MIN(C24,0.04)*50)+(MIN(D24,1)*4)+(IF(E24="Great Power",1.5,IF(E24="Secondary Power",1.25,IF(E24="Westernized Nation",1,0)))) -> 5.6631326 | G24: =MIN(G23+(4*2/90/100*12),1) -> 0.53466667 | H24: 1 | I24: =F24*(1+H24+G24) -> 14.354153 | J24: =I24*365 -> 5239.266 | L24: 1852 | M24: =MAX((M23+K24-J24)*0.994,0) -> 432999.91
A25: 1853 | B25: 0.0276 | C25: 0.0087 | D25: 0.1915 | E25: Great Power | F25: =(MIN(B25,0.02)*150)+(MIN(C25,0.04)*50)+(MIN(D25,1)*4)+(IF(E25="Great Power",1.5,IF(E25="Secondary Power",1.25,IF(E25="Westernized Nation",1,0)))) -> 5.701 | G25: =MIN(G24+(4*2/90/100*12),1) -> 0.54533333 | H25: 1 | I25: =F25*(1+H25+G25) -> 14.510945 | J25: =I25*365 -> 5296.495 | L25: 1853 | M25: =MAX((M24+K25-J25)*0.994,0) -> 425137.2
A26: 1854 | B26: 0.0284 | C26: 0.0089 | D26: 0.19925029 | E26: Great Power | F26: =(MIN(B26,0.02)*150)+(MIN(C26,0.04)*50)+(MIN(D26,1)*4)+(IF(E26="Great Power",1.5,IF(E26="Secondary Power",1.25,IF(E26="Westernized Nation",1,0)))) -> 5.7420011 | G26: =MIN(G25+(4*2/90/100*12),1) -> 0.556 | H26: 1 | I26: =F26*(1+H26+G26) -> 14.676555 | J26: =I26*365 -> 5356.9425 | L26: 1854 | M26: =MAX((M25+K26-J26)*0.994,0) -> 417261.57
A27: 1855 | B27: 0.0292 | C27: 0.0091 | D27: 0.20723543 | E27: Great Power | F27: =(MIN(B27,0.02)*150)+(MIN(C27,0.04)*50)+(MIN(D27,1)*4)+(IF(E27="Great Power",1.5,IF(E27="Secondary Power",1.25,IF(E27="Westernized Nation",1,0)))) -> 5.7839417 | G27: =MIN(G26+(4*2/90/100*12),1) -> 0.56666667 | H27: 1 | I27: =F27*(1+H27+G27) -> 14.84545 | J27: =I27*365 -> 5418.5894 | K27: 21600 | L27: 1855 | M27: =MAX((M26+K27-J27)*0.994,0) -> 430842.32
A28: 1856 | B28: 0.03 | C28: 0.0093 | D28: 0.21575543 | E28: Great Power | F28: =(MIN(B28,0.02)*150)+(MIN(C28,0.04)*50)+(MIN(D28,1)*4)+(IF(E28="Great Power",1.5,IF(E28="Secondary Power",1.25,IF(E28="Westernized Nation",1,0)))) -> 5.8280217 | G28: =MIN(G27+(4*2/90/100*12),1) -> 0.57733333 | H28: 1 | I28: =F28*(1+H28+G28) -> 15.020755 | J28: =I28*365 -> 5482.5754 | L28: 1856 | M28: =MAX((M27+K28-J28)*0.994,0) -> 422807.59
A29: 1857 | B29: 0.0308 | C29: 0.0095 | D29: 0.22637029 | E29: Great Power | F29: =(MIN(B29,0.02)*150)+(MIN(C29,0.04)*50)+(MIN(D29,1)*4)+(IF(E29="Great Power",1.5,IF(E29="Secondary Power",1.25,IF(E29="Westernized Nation",1,0)))) -> 5.8804811 | G29: =MIN(G28+(4*2/90/100*12),1) -> 0.588 | H29: 1 | I29: =F29*(1+H29+G29) -> 15.218685 | J29: =I29*365 -> 5554.8201 | L29: 1857 | M29: =MAX((M28+K29-J29)*0.994,0) -> 414749.25
A30: 1858 | B30: 0.0316 | C30: 0.0097 | D30: 0.23728 | E30: Great Power | F30: =(MIN(B30,0.02)*150)+(MIN(C30,0.04)*50)+(MIN(D30,1)*4)+(IF(E30="Great Power",1.5,IF(E30="Secondary Power",1.25,IF(E30="Westernized Nation",1,0)))) -> 5.93412 | G30: =MIN(G29+(4*2/90/100*12),1) -> 0.59866667 | H30: 1 | I30: =F30*(1+H30+G30) -> 15.4208 | J30: =I30*365 -> 5628.5919 | L30: 1858 | M30: =MAX((M29+K30-J30)*0.994,0) -> 406665.94
A31: 1859 | B31: 0.0324 | C31: 0.0099 | D31: 0.24848457 | E31: Great Power | F31: =(MIN(B31,0.02)*150)+(MIN(C31,0.04)*50)+(MIN(D31,1)*4)+(IF(E31="Great Power",1.5,IF(E31="Secondary Power",1.25,IF(E31="Westernized Nation",1,0)))) -> 5.9889383 | G31: =MIN(G30+(4*2/90/100*12),1) -> 0.60933333 | H31: 1 | I31: =F31*(1+H31+G31) -> 15.627136 | J31: =I31*365 -> 5703.9047 | L31: 1859 | M31: =MAX((M30+K31-J31)*0.994,0) -> 398556.26
A32: 1860 | B32: 0.0332 | C32: 0.0101 | D32: 0.259984 | E32: Great Power | F32: =(MIN(B32,0.02)*150)+(MIN(C32,0.04)*50)+(MIN(D32,1)*4)+(IF(E32="Great Power",1.5,IF(E32="Secondary Power",1.25,IF(E32="Westernized Nation",1,0)))) -> 6.044936 | G32: =MIN(G31+(4*2/90/100*12),1) -> 0.62 | H32: 1 | I32: =F32*(1+H32+G32) -> 15.837732 | J32: =I32*365 -> 5780.7723 | K32: 10800 | L32: 1860 | M32: =MAX((M31+K32-J32)*0.994,0) -> 401154.04
A33: 1861 | B33: 0.034 | C33: 0.0103 | D33: 0.27177829 | E33: Great Power | F33: =(MIN(B33,0.02)*150)+(MIN(C33,0.04)*50)+(MIN(D33,1)*4)+(IF(E33="Great Power",1.5,IF(E33="Secondary Power",1.25,IF(E33="Westernized Nation",1,0)))) -> 6.1021131 | G33: =MIN(G32+(4*2/90/100*12),1) -> 0.63066667 | H33: 1.5 | I33: =F33*(1+H33+G33) -> 19.103682 | J33: =I33*365 -> 6972.844 | L33: 1861 | M33: =MAX((M32+K33-J33)*0.994,0) -> 391816.11
A34: 1862 | B34: 0.0348 | C34: 0.0105 | D34: 0.28386743 | E34: Great Power | F34: =(MIN(B34,0.02)*150)+(MIN(C34,0.04)*50)+(MIN(D34,1)*4)+(IF(E34="Great Power",1.5,IF(E34="Secondary Power",1.25,IF(E34="Westernized Nation",1,0)))) -> 6.1604697 | G34: =MIN(G33+(4*2/90/100*12),1) -> 0.64133333 | H34: 1.5 | I34: =F34*(1+H34+G34) -> 19.352089 | J34: =I34*365 -> 7063.5124 | L34: 1862 | M34: =MAX((M33+K34-J34)*0.994,0) -> 382444.08
A35: 1863 | B35: 0.0356 | C35: 0.0107 | D35: 0.29625143 | E35: Great Power | F35: =(MIN(B35,0.02)*150)+(MIN(C35,0.04)*50)+(MIN(D35,1)*4)+(IF(E35="Great Power",1.5,IF(E35="Secondary Power",1.25,IF(E35="Westernized Nation",1,0)))) -> 6.2200057 | G35: =MIN(G34+(4*2/90/100*12),1) -> 0.652 | H35: 1.5 | I35: =F35*(1+H35+G35) -> 19.605458 | J35: =I35*365 -> 7155.9922 | L35: 1863 | M35: =MAX((M34+K35-J35)*0.994,0) -> 373036.36
A36: 1864 | B36: 0.0364 | C36: 0.0109 | D36: 0.30966743 | E36: Great Power | F36: =(MIN(B36,0.02)*150)+(MIN(C36,0.04)*50)+(MIN(D36,1)*4)+(IF(E36="Great Power",1.5,IF(E36="Secondary Power",1.25,IF(E36="Westernized Nation",1,0)))) -> 6.2836697 | G36: =MIN(G35+(4*2/90/100*12),1) -> 0.66266667 | H36: 1.5 | I36: =F36*(1+H36+G36) -> 19.873153 | J36: =I36*365 -> 7253.7008 | L36: 1864 | M36: =MAX((M35+K36-J36)*0.994,0) -> 363587.96
A37: 1865 | B37: 0.0372 | C37: 0.0111 | D37: 0.32339543 | E37: Great Power | F37: =(MIN(B37,0.02)*150)+(MIN(C37,0.04)*50)+(MIN(D37,1)*4)+(IF(E37="Great Power",1.5,IF(E37="Secondary Power",1.25,IF(E37="Westernized Nation",1,0)))) -> 6.3485817 | G37: =MIN(G36+(4*2/90/100*12),1) -> 0.67333333 | H37: 1.5 | I37: =F37*(1+H37+G37) -> 20.146166 | J37: =I37*365 -> 7353.3506 | L37: 1865 | M37: =MAX((M36+K37-J37)*0.994,0) -> 354097.2
A38: 1866 | B38: 0.038 | C38: 0.0113 | D38: 0.33743543 | E38: Great Power | F38: =(MIN(B38,0.02)*150)+(MIN(C38,0.04)*50)+(MIN(D38,1)*4)+(IF(E38="Great Power",1.5,IF(E38="Secondary Power",1.25,IF(E38="Westernized Nation",1,0)))) -> 6.4147417 | G38: =MIN(G37+(4*2/90/100*12),1) -> 0.684 | H38: 1.5 | I38: =F38*(1+H38+G38) -> 20.424538 | J38: =I38*365 -> 7454.9562 | L38: 1866 | M38: =MAX((M37+K38-J38)*0.994,0) -> 344562.39
A39: 1867 | B39: 0.0388 | C39: 0.0115 | D39: 0.35178743 | E39: Great Power | F39: =(MIN(B39,0.02)*150)+(MIN(C39,0.04)*50)+(MIN(D39,1)*4)+(IF(E39="Great Power",1.5,IF(E39="Secondary Power",1.25,IF(E39="Westernized Nation",1,0)))) -> 6.4821497 | G39: =MIN(G38+(4*2/90/100*12),1) -> 0.69466667 | H39: 1.5 | I39: =F39*(1+H39+G39) -> 20.708308 | J39: =I39*365 -> 7558.5323 | L39: 1867 | M39: =MAX((M38+K39-J39)*0.994,0) -> 334981.84
A40: 1868 | B40: 0.0396 | C40: 0.0117 | D40: 0.36645143 | E40: Great Power | F40: =(MIN(B40,0.02)*150)+(MIN(C40,0.04)*50)+(MIN(D40,1)*4)+(IF(E40="Great Power",1.5,IF(E40="Secondary Power",1.25,IF(E40="Westernized Nation",1,0)))) -> 6.5508057 | G40: =MIN(G39+(4*2/90/100*12),1) -> 0.70533333 | H40: 1.5 | I40: =F40*(1+H40+G40) -> 20.997516 | J40: =I40*365 -> 7664.0933 | L40: 1868 | M40: =MAX((M39+K40-J40)*0.994,0) -> 325353.84
...

Sheet Tech Cost
A1: Date | B1: Total Tech Cost | D1: Name of period | E1: Amount | F1: Total Cost | H1: Date | I1: Total Technology Cost
A2: 1830 | B2: =$I$2*(1-(A2-1830)*2/300) -> 244800 | D2: 1830 first | E2: 25 x 3600 | F2: 90000 | H2: 1830 | I2: =IF(H23="Yes",SUM(F2,F3,F4),SUM(F3,F4)) -> 244800
A3: 1831 | B3: =$I$2*(1-(A3-1830)*2/300) -> 243168 | D3: 1830 second | E3: 22 x 7200 | F3: 158400 | H3: 1840 | I3: =SUM(F5,F6) -> 32400
A4: 1832 | B4: =$I$2*(1-(A4-1830)*2/300) -> 241536 | D4: 1830 third | E4: 8 x 10800 | F4: 86400 | H4: 1848 | I4: =SUM(F7) -> 10800
A5: 1833 | B5: =$I$2*(1-(A5-1830)*2/300) -> 239904 | D5: 1840 second | E5: 3 x 7200 | F5: 21600 | H5: 1850 | I5: =SUM(F8,F9) -> 259200
A6: 1834 | B6: =$I$2*(1-(A6-1830)*2/300) -> 238272 | D6: 1840 third | E6: 1 x 10800 | F6: 10800 | H6: 1855 | I6: =SUM(F10) -> 21600
A7: 1835 | B7: =$I$2*(1-(A7-1830)*2/300) -> 236640 | D7: 1848 third | E7: 1 x 10800 | F7: 10800 | H7: 1860 | I7: =SUM(F11) -> 10800
A8: 1836 | B8: =$I$2*(1-(A8-1830)*2/300) -> 235008 | D8: 1850 third | E8: 12 x 10800 | F8: 129600 | H8: 1870 | I8: =SUM(F12,F13) -> 331200
A9: 1837 | B9: =$I$2*(1-(A9-1830)*2/300) -> 233376 | D9: 1850 fourth | E9: 9 x 14400 | F9: 129600 | H9: 1872 | I9: =SUM(F14) -> 14400
A10: 1838 | B10: =$I$2*(1-(A10-1830)*2/300) -> 231744 | D10: 1855 third | E10: 2 x 10800 | F10: 21600 | H10: 1875 | I10: =SUM(F15) -> 14400
A11: 1839 | B11: =$I$2*(1-(A11-1830)*2/300) -> 230112 | D11: 1860 third | E11: 1 x 10800 | F11: 10800 | H11: 1880 | I11: =SUM(F16,F17) -> 50400
A12: 1840 | B12: =$I$2*(1-(A12-1830)*2/300)+$I$3*(1-(A12-1840)*2/300) -> 260880 | D12: 1870 fourth | E12: 13 x 14400 | F12: 187200 | H12: 1890 | I12: =SUM(F18) -> 54000
A13: 1841 | B13: =$I$2*(1-(A13-1830)*2/300)+$I$3*(1-(A13-1840)*2/300) -> 259032 | D13: 1870 fifth | E13: 8 x 18000 | F13: 144000 | H13: 1895 | I13: =SUM(F19) -> 18000
A14: 1842 | B14: =$I$2*(1-(A14-1830)*2/300)+$I$3*(1-(A14-1840)*2/300) -> 257184 | D14: 1872 fourth | E14: 1 x 14400 | F14: 14400 | H14: 1898 | I14: =SUM(F20) -> 18000
A15: 1843 | B15: =$I$2*(1-(A15-1830)*2/300)+$I$3*(1-(A15-1840)*2/300) -> 255336 | D15: 1875 fourth | E15: 1 x 14400 | F15: 14400 | H15: 1900 | I15: =SUM(F21,F22) -> 255600
A16: 1844 | B16: =$I$2*(1-(A16-1830)*2/300)+$I$3*(1-(A16-1840)*2/300) -> 253488 | D16: 1880 fourth | E16: 1 x 14400 | F16: 14400 | H16: 1905 | I16: =SUM(F23) -> 21600
A17: 1845 | B17: =$I$2*(1-(A17-1830)*2/300)+$I$3*(1-(A17-1840)*2/300) -> 251640 | D17: 1880 fifth | E17: 2 x 18000 | F17: 36000 | H17: 1910 | I17: =SUM(F24) -> 21600
A18: 1846 | B18: =$I$2*(1-(A18-1830)*2/300)+$I$3*(1-(A18-1840)*2/300) -> 249792 | D18: 1890 fifth | E18: 3 x 18000 | F18: 54000 | H18: 1914 | I18: =SUM(F25) -> 43200
A19: 1847 | B19: =$I$2*(1-(A19-1830)*2/300)+$I$3*(1-(A19-1840)*2/300) -> 247944 | D19: 1895 fifth | E19: 1 x 18000 | F19: 18000 | H19: 1915 | I19: =SUM(F26) -> 21600
A20: 1848 | B20: =$I$2*(1-(A20-1830)*2/300)+$I$3*(1-(A20-1840)*2/300)+$I$4*(1-(A20-1848)*2/300) -> 256896 | D20: 1898 fifth | E20: 1 x 18000 | F20: 18000 | H20: 1919 | I20: =SUM(F27) -> 194400
A21: 1849 | B21: =$I$2*(1-(A21-1830)*2/300)+$I$3*(1-(A21-1840)*2/300)+$I$4*(1-(A21-1848)*2/300) -> 254976 | D21: 1900 fifth | E21: 10 x 1800 | F21: 18000 | H21: SUM | I21: =SUM(I2:I20) -> 1638000
A22: 1850 | B22: =$I$2*(1-(A22-1830)*2/300)+$I$3*(1-(A22-1840)*2/300)+$I$4*(1-(A22-1848)*2/300)+$I$5*(1-(A22-1850)*2/300) -> 512256 | D22: 1900 sixth | E22: 11 x 21600 | F22: 237600
A23: 1851 | B23: =$I$2*(1-(A23-1830)*2/300)+$I$3*(1-(A23-1840)*2/300)+$I$4*(1-(A23-1848)*2/300)+$I$5*(1-(A23-1850)*2/300) -> 508608 | D23: 1905 sixth | E23: 1 x 21600 | F23: 21600 | H23: No | I23: Inc. base techs?
A24: 1852 | B24: =$I$2*(1-(A24-1830)*2/300)+$I$3*(1-(A24-1840)*2/300)+$I$4*(1-(A24-1848)*2/300)+$I$5*(1-(A24-1850)*2/300) -> 504960 | D24: 1910 sixth | E24: 1 x 21600 | F24: 21600
A25: 1853 | B25: =$I$2*(1-(A25-1830)*2/300)+$I$3*(1-(A25-1840)*2/300)+$I$4*(1-(A25-1848)*2/300)+$I$5*(1-(A25-1850)*2/300) -> 501312 | D25: 1914 sixth | E25: 2 x 21600 | F25: 43200
A26: 1854 | B26: =$I$2*(1-(A26-1830)*2/300)+$I$3*(1-(A26-1840)*2/300)+$I$4*(1-(A26-1848)*2/300)+$I$5*(1-(A26-1850)*2/300) -> 497664 | D26: 1915 sixth | E26: 1 x 21600 | F26: 21600
A27: 1855 | B27: =$I$2*(1-(A27-1830)*2/300)+$I$3*(1-(A27-1840)*2/300)+$I$4*(1-(A27-1848)*2/300)+$I$5*(1-(A27-1850)*2/300)+$I$6*(1-(A27-1855)*2/300) -> 515616 | D27: 1919 sixth | E27: 9 x 21600 | F27: 194400
A28: 1856 | B28: =$I$2*(1-(A28-1830)*2/300)+$I$3*(1-(A28-1840)*2/300)+$I$4*(1-(A28-1848)*2/300)+$I$5*(1-(A28-1850)*2/300)+$I$6*(1-(A28-1855)*2/300) -> 511824
A29: 1857 | B29: =$I$2*(1-(A29-1830)*2/300)+$I$3*(1-(A29-1840)*2/300)+$I$4*(1-(A29-1848)*2/300)+$I$5*(1-(A29-1850)*2/300)+$I$6*(1-(A29-1855)*2/300) -> 508032
A30: 1858 | B30: =$I$2*(1-(A30-1830)*2/300)+$I$3*(1-(A30-1840)*2/300)+$I$4*(1-(A30-1848)*2/300)+$I$5*(1-(A30-1850)*2/300)+$I$6*(1-(A30-1855)*2/300) -> 504240
A31: 1859 | B31: =$I$2*(1-(A31-1830)*2/300)+$I$3*(1-(A31-1840)*2/300)+$I$4*(1-(A31-1848)*2/300)+$I$5*(1-(A31-1850)*2/300)+$I$6*(1-(A31-1855)*2/300) -> 500448
A32: 1860 | B32: =$I$2*(1-(A32-1830)*2/300)+$I$3*(1-(A32-1840)*2/300)+$I$4*(1-(A32-1848)*2/300)+$I$5*(1-(A32-1850)*2/300)+$I$6*(1-(A32-1855)*2/300)+$I$2*(1-(A32-1860)*2/300) -> 741456
A33: 1861 | B33: =$I$2*(1-(A33-1830)*2/300)+$I$3*(1-(A33-1840)*2/300)+$I$4*(1-(A33-1848)*2/300)+$I$5*(1-(A33-1850)*2/300)+$I$6*(1-(A33-1855)*2/300)+$I$2*(1-(A33-1860)*2/300) -> 736032
A34: 1862 | B34: =$I$2*(1-(A34-1830)*2/300)+$I$3*(1-(A34-1840)*2/300)+$I$4*(1-(A34-1848)*2/300)+$I$5*(1-(A34-1850)*2/300)+$I$6*(1-(A34-1855)*2/300)+$I$2*(1-(A34-1860)*2/300) -> 730608
A35: 1863 | B35: =$I$2*(1-(A35-1830)*2/300)+$I$3*(1-(A35-1840)*2/300)+$I$4*(1-(A35-1848)*2/300)+$I$5*(1-(A35-1850)*2/300)+$I$6*(1-(A35-1855)*2/300)+$I$2*(1-(A35-1860)*2/300) -> 725184
A36: 1864 | B36: =$I$2*(1-(A36-1830)*2/300)+$I$3*(1-(A36-1840)*2/300)+$I$4*(1-(A36-1848)*2/300)+$I$5*(1-(A36-1850)*2/300)+$I$6*(1-(A36-1855)*2/300)+$I$2*(1-(A36-1860)*2/300) -> 719760
A37: 1865 | B37: =$I$2*(1-(A37-1830)*2/300)+$I$3*(1-(A37-1840)*2/300)+$I$4*(1-(A37-1848)*2/300)+$I$5*(1-(A37-1850)*2/300)+$I$6*(1-(A37-1855)*2/300)+$I$2*(1-(A37-1860)*2/300) -> 714336
A38: 1866 | B38: =$I$2*(1-(A38-1830)*2/300)+$I$3*(1-(A38-1840)*2/300)+$I$4*(1-(A38-1848)*2/300)+$I$5*(1-(A38-1850)*2/300)+$I$6*(1-(A38-1855)*2/300)+$I$2*(1-(A38-1860)*2/300) -> 708912
A39: 1867 | B39: =$I$2*(1-(A39-1830)*2/300)+$I$3*(1-(A39-1840)*2/300)+$I$4*(1-(A39-1848)*2/300)+$I$5*(1-(A39-1850)*2/300)+$I$6*(1-(A39-1855)*2/300)+$I$2*(1-(A39-1860)*2/300) -> 703488
A40: 1868 | B40: =$I$2*(1-(A40-1830)*2/300)+$I$3*(1-(A40-1840)*2/300)+$I$4*(1-(A40-1848)*2/300)+$I$5*(1-(A40-1850)*2/300)+$I$6*(1-(A40-1855)*2/300)+$I$2*(1-(A40-1860)*2/300) -> 698064
...

Sheet Education Efficiency
A1: Date | B1: Tech Education Efficiency | C1: Reforms | D1: Intellectualists | E1: Literacy | F1: Literacy Change
A2: 1830 | B2: 0.1 | C2: -0.1 | D2: 0.01 | E2: 0.512 | F2: =(D2-0.005)*0.1/0.035*(1+B2+C2)*0.01*120 -> 0.017142857
A3: 1840 | B3: 0.2 | C3: -0.03 | D3: 0.02 | E3: =MIN(1,E2+F2) -> 0.52914286 | F3: =(D3-0.005)*0.1/0.035*(1+B3+C3)*0.01*120 -> 0.060171429
A4: 1850 | B4: 0.7 | C4: 0.02 | D4: 0.025 | E4: =MIN(1,E3+F3) -> 0.58931429 | F4: =(D4-0.005)*0.1/0.035*(1+B4+C4)*0.01*120 -> 0.11794286
A5: 1860 | B5: 0.7 | C5: 0.17 | D5: 0.03 | E5: =MIN(1,E4+F4) -> 0.70725714 | F5: =(D5-0.005)*0.1/0.035*(1+B5+C5)*0.01*120 -> 0.16028571
A6: 1870 | B6: 0.9 | C6: 0.32 | D6: 0.04 | E6: =MIN(1,E5+F5) -> 0.86754286 | F6: =(D6-0.005)*0.1/0.035*(1+B6+C6)*0.01*120 -> 0.2664
A7: 1880 | B7: 0.9 | C7: 0.32 | D7: 0.04 | E7: =MIN(1,E6+F6) -> 1 | F7: =(D7-0.005)*0.1/0.035*(1+B7+C7)*0.01*120 -> 0.2664
A8: 1890 | B8: 1.15 | C8: 0.32 | D8: 0.04 | E8: =MIN(1,E7+F7) -> 1 | F8: =(D8-0.005)*0.1/0.035*(1+B8+C8)*0.01*120 -> 0.2964
A9: 1900 | B9: 1.35 | C9: 0.32 | D9: 0.04 | E9: =MIN(1,E8+F8) -> 1 | F9: =(D9-0.005)*0.1/0.035*(1+B9+C9)*0.01*120 -> 0.3204
A10: 1910 | B10: 1.35 | C10: 0.32 | D10: 0.04 | E10: =MIN(1,E9+F9) -> 1 | F10: =(D10-0.005)*0.1/0.035*(1+B10+C10)*0.01*120 -> 0.3204
A11: 1920 | B11: 1.35 | C11: 0.32 | D11: 0.04 | E11: =MIN(1,E10+F10) -> 1 | F11: =(D11-0.005)*0.1/0.035*(1+B11+C11)*0.01*120 -> 0.3204
A12: 1930 | B12: 1.35 | C12: 0.32 | D12: 0.04 | E12: =MIN(1,E11+F11) -> 1 | F12: =(D12-0.005)*0.1/0.035*(1+B12+C12)*0.01*120 -> 0.3204
A14: TEST | B14: 0 | C14: 0 | D14: 0.04 | E14: 0.01 | F14: =(D14-0.005)*0.1/0.035*(1+B14+C14)*0.01*120 -> 0.12
A15: TEST | B15: 0 | C15: 0 | D15: 0.04 | E15: =SUM(E14,F14) -> 0.13 | F15: =(D15-0.005)*0.1/0.035*(1+B15+C15)*0.01*120 -> 0.12
A17: TEST | B17: 1 | C17: 0 | D17: 0.01 | E17: 0.01 | F17: =(D17-0.005)*0.1/0.035*(1+B17+C17)*0.01*120 -> 0.034285714
A18: TEST | B18: 1 | C18: 0 | D18: 0.04 | E18: =SUM(E17,F17) -> 0.044285714 | F18: =(D18-0.005)*0.1/0.035*(1+B18+C18)*0.01*120 -> 0.24
A20: Date | B20: Tech Education Efficiency | C20: Reforms | D20: Intellectualists | E20: Literacy | F20: Literacy Change
A21: 1830 | B21: 0.1 | C21: -0.1 | D21: 0.01 | E21: 0.1 | F21: =(D21-0.005)*0.1/0.035*(1+B21+C21)*0.01*12 -> 0.0017142857
A22: 1831 | B22: 0.1 | C22: -0.1 | D22: 0.0105 | E22: =MIN(1,E21+F21) -> 0.10171429 | F22: =(D22-0.005)*0.1/0.035*(1+B22+C22)*0.01*12 -> 0.0018857143
A23: 1832 | B23: 0.1 | C23: -0.1 | D23: 0.011 | E23: =MIN(1,E22+F22) -> 0.1036 | F23: =(D23-0.005)*0.1/0.035*(1+B23+C23)*0.01*12 -> 0.0020571429
A24: 1833 | B24: 0.1 | C24: -0.1 | D24: 0.0115 | E24: =MIN(1,E23+F23) -> 0.10565714 | F24: =(D24-0.005)*0.1/0.035*(1+B24+C24)*0.01*12 -> 0.0022285714
A25: 1834 | B25: 0.1 | C25: -0.1 | D25: 0.012 | E25: =MIN(1,E24+F24) -> 0.10788571 | F25: =(D25-0.005)*0.1/0.035*(1+B25+C25)*0.01*12 -> 0.0024
A26: 1835 | B26: 0.1 | C26: -0.1 | D26: 0.0125 | E26: =MIN(1,E25+F25) -> 0.11028571 | F26: =(D26-0.005)*0.1/0.035*(1+B26+C26)*0.01*12 -> 0.0025714286
A27: 1836 | B27: 0.1 | C27: -0.1 | D27: 0.013 | E27: =MIN(1,E26+F26) -> 0.11285714 | F27: =(D27-0.005)*0.1/0.035*(1+B27+C27)*0.01*12 -> 0.0027428571
A28: 1837 | B28: 0.1 | C28: -0.1 | D28: 0.0135 | E28: =MIN(1,E27+F27) -> 0.1156 | F28: =(D28-0.005)*0.1/0.035*(1+B28+C28)*0.01*12 -> 0.0029142857
A29: 1838 | B29: 0.1 | C29: -0.1 | D29: 0.014 | E29: =MIN(1,E28+F28) -> 0.11851429 | F29: =(D29-0.005)*0.1/0.035*(1+B29+C29)*0.01*12 -> 0.0030857143
A30: 1839 | B30: 0.1 | C30: -0.1 | D30: 0.0145 | E30: =MIN(1,E29+F29) -> 0.1216 | F30: =(D30-0.005)*0.1/0.035*(1+B30+C30)*0.01*12 -> 0.0032571429
A31: 1840 | B31: 0.1 | C31: -0.1 | D31: 0.015 | E31: =MIN(1,E30+F30) -> 0.12485714 | F31: =(D31-0.005)*0.1/0.035*(1+B31+C31)*0.01*12 -> 0.0034285714
A32: 1841 | B32: 0.1 | C32: -0.1 | D32: 0.0155 | E32: =MIN(1,E31+F31) -> 0.12828571 | F32: =(D32-0.005)*0.1/0.035*(1+B32+C32)*0.01*12 -> 0.0036
A33: 1842 | B33: 0.1 | C33: -0.1 | D33: 0.016 | E33: =MIN(1,E32+F32) -> 0.13188571 | F33: =(D33-0.005)*0.1/0.035*(1+B33+C33)*0.01*12 -> 0.0037714286
... A127: 1936 | B127: 1.35 | C127: 0.32 | D127: 0.04 | E127: =MIN(1,E126+F126) -> 1 | F127: =(D127-0.005)*0.1/0.035*(1+B127+C127)*0.01*12 -> 0.03204

Sheet State Sim
A1: Date | B1: POPs | C1: Intellectuals | D1: Bureaucrats | E1: Intellectuals % | F1: Bureaucrats % | G1: Literacy | H1: Administrative Efficiency | I1: Admin Eff. Bonus | J1: Reforms Taken | K1: Promotions | L1: To Intellectualists | M1: To Bureaucrats | N1: Slave State? | O1: Edu Spending | P1: Admin Spending | Q1: Life Rating | R1: POP Growth | V1: Promotion - General
A2: 1830 | B2: 100000 | C2: 0 | D2: 0 | E2: =C2/B2 -> 0 | F2: =D2/B2 -> 0 | G2: 0.01 | H2: =MIN((D2/B2)/(0.01+(J2*0.001))+I2,1) -> 0.4 | I2: 0.4 | J2: 0 | K2: =B2/500/4*(0.3-IF($N$2="Yes",0.1,0)+VLOOKUP(G2,$V$3:$W$11,2,1))*H2*12 -> 72 | L2: =(VLOOKUP(G2,$T$15:$U$21,2,1)+VLOOKUP($O$2,$T$26:$U$36,2,1)-0.12)*IF(E2>0.041,0,1) -> 0.14 | M2: =VLOOKUP(G2,$X$15:$Y$22,2,1)+VLOOKUP($P$2,$X$26:$Y$37,2,1)*IF(F2>0.04,0,1) -> 0.02 | N2: No | O2: 1 | P2: 0.1 | Q2: 35 | R2: 0 | V2: Literacy | W2: Total Bonus | X2: Bonus
A3: 1831 | B3: =B2*(1+MAX(($Q$2-30)*0.0001+0.0001+$R$2,0))-K2 -> 99988 | C3: =C2*(1+MAX(($Q$2-30)*0.0001+0.0001+$R$2,0))+K2*IF(M2=0,1,L2/M2) -> 504 | D3: =D2*(1+MAX(($Q$2-30)*0.0001+0.0001+$R$2,0))+K2*IF(L2=0,1,M2/L2) -> 10.285714 | E3: =C3/B3 -> 0.0050406049 | F3: =D3/B3 -> 0.00010286949 | G3: 0.01 | H3: =MIN((D3/B3)/(0.01+(J3*0.001))+I3,1) -> 0.41028695 | I3: 0.4 | J3: 0 | K3: =B3/500/4*(0.3-IF($N$2="Yes",0.1,0)+VLOOKUP(G3,$V$3:$W$11,2,TRUE()))*H3*12 -> 73.842789 | L3: =(VLOOKUP(G3,$T$15:$U$21,2,1)+VLOOKUP($O$2,$T$26:$U$36,2,1)-0.12)*IF(E3>0.041,0,1) -> 0.14 | M3: =VLOOKUP(G3,$X$15:$Y$22,2,1)+VLOOKUP($P$2,$X$26:$Y$37,2,1)*IF(F3>0.04,0,1) -> 0.02 | V3: 0 | W3: =SUM(X3) -> 0 | X3: 0
A4: 1832 | B4: =B3*(1+MAX(($Q$2-30)*0.0001+0.0001+$R$2,0))-K3 -> 99974.15 | C4: =C3*(1+MAX(($Q$2-30)*0.0001+0.0001+$R$2,0))+K3*IF(M3=0,1,L3/M3) -> 1021.2019 | D4: =D3*(1+MAX(($Q$2-30)*0.0001+0.0001+$R$2,0))+K3*IF(L3=0,1,M3/L3) -> 20.840856 | E4: =C4/B4 -> 0.01021466 | F4: =D4/B4 -> 0.00020846244 | G4: 0.01 | H4: =MIN((D4/B4)/(0.01+(J4*0.001))+I4,1) -> 0.42084624 | I4: 0.4 | J4: 0 | K4: =B4/500/4*(0.3-IF($N$2="Yes",0.1,0)+VLOOKUP(G4,$V$3:$W$11,2,TRUE()))*H4*12 -> 75.732742 | L4: =(VLOOKUP(G4,$T$15:$U$21,2,1)+VLOOKUP($O$2,$T$26:$U$36,2,1)-0.12)*IF(E4>0.041,0,1) -> 0.14 | M4: =VLOOKUP(G4,$X$15:$Y$22,2,1)+VLOOKUP($P$2,$X$26:$Y$37,2,1)*IF(F4>0.04,0,1) -> 0.02 | V4: 0.1 | W4: =SUM(X3:X4) -> 0.032 | X4: 0.032
A5: 1833 | B5: =B4*(1+MAX(($Q$2-30)*0.0001+0.0001+$R$2,0))-K4 -> 99958.402 | C5: =C4*(1+MAX(($Q$2-30)*0.0001+0.0001+$R$2,0))+K4*IF(M4=0,1,L4/M4) -> 1551.9438 | D5: =D4*(1+MAX(($Q$2-30)*0.0001+0.0001+$R$2,0))+K4*IF(L4=0,1,M4/L4) -> 31.672323 | E5: =C5/B5 -> 0.015525897 | F5: =D5/B5 -> 0.00031685504 | G5: 0.01 | H5: =MIN((D5/B5)/(0.01+(J5*0.001))+I5,1) -> 0.4316855 | I5: 0.4 | J5: 0 | K5: =B5/500/4*(0.3-IF($N$2="Yes",0.1,0)+VLOOKUP(G5,$V$3:$W$11,2,TRUE()))*H5*12 -> 77.671067 | L5: =(VLOOKUP(G5,$T$15:$U$21,2,1)+VLOOKUP($O$2,$T$26:$U$36,2,1)-0.12)*IF(E5>0.041,0,1) -> 0.14 | M5: =VLOOKUP(G5,$X$15:$Y$22,2,1)+VLOOKUP($P$2,$X$26:$Y$37,2,1)*IF(F5>0.04,0,1) -> 0.02 | V5: 0.2 | W5: =SUM(X3:X5) -> 0.055 | X5: 0.023
A6: 1834 | B6: =B5*(1+MAX(($Q$2-30)*0.0001+0.0001+$R$2,0))-K5 -> 99940.706 | C6: =C5*(1+MAX(($Q$2-30)*0.0001+0.0001+$R$2,0))+K5*IF(M5=0,1,L5/M5) -> 2096.5725 | D6: =D5*(1+MAX(($Q$2-30)*0.0001+0.0001+$R$2,0))+K5*IF(L5=0,1,M5/L5) -> 42.787193 | E6: =C6/B6 -> 0.020978164 | F6: =D6/B6 -> 0.00042812579 | G6: 0.01 | H6: =MIN((D6/B6)/(0.01+(J6*0.001))+I6,1) -> 0.44281258 | I6: 0.4 | J6: 0 | K6: =B6/500/4*(0.3-IF($N$2="Yes",0.1,0)+VLOOKUP(G6,$V$3:$W$11,2,TRUE()))*H6*12 -> 79.659003 | L6: =(VLOOKUP(G6,$T$15:$U$21,2,1)+VLOOKUP($O$2,$T$26:$U$36,2,1)-0.12)*IF(E6>0.041,0,1) -> 0.14 | M6: =VLOOKUP(G6,$X$15:$Y$22,2,1)+VLOOKUP($P$2,$X$26:$Y$37,2,1)*IF(F6>0.04,0,1) -> 0.02 | V6: 0.3 | W6: =SUM(X3:X6) -> 0.076 | X6: 0.021
A7: 1835 | B7: =B6*(1+MAX(($Q$2-30)*0.0001+0.0001+$R$2,0))-K6 -> 99921.011 | C7: =C6*(1+MAX(($Q$2-30)*0.0001+0.0001+$R$2,0))+K6*IF(M6=0,1,L6/M6) -> 2655.4434 | D7: =D6*(1+MAX(($Q$2-30)*0.0001+0.0001+$R$2,0))+K6*IF(L6=0,1,M6/L6) -> 54.192723 | E7: =C7/B7 -> 0.026575426 | F7: =D7/B7 -> 0.00054235563 | G7: 0.01 | H7: =MIN((D7/B7)/(0.01+(J7*0.001))+I7,1) -> 0.45423556 | I7: 0.4 | J7: 0 | K7: =B7/500/4*(0.3-IF($N$2="Yes",0.1,0)+VLOOKUP(G7,$V$3:$W$11,2,TRUE()))*H7*12 -> 81.697818 | L7: =(VLOOKUP(G7,$T$15:$U$21,2,1)+VLOOKUP($O$2,$T$26:$U$36,2,1)-0.12)*IF(E7>0.041,0,1) -> 0.14 | M7: =VLOOKUP(G7,$X$15:$Y$22,2,1)+VLOOKUP($P$2,$X$26:$Y$37,2,1)*IF(F7>0.04,0,1) -> 0.02 | V7: 0.4 | W7: =SUM(X3:X7) -> 0.096 | X7: 0.02
A8: 1836 | B8: =B7*(1+MAX(($Q$2-30)*0.0001+0.0001+$R$2,0))-K7 -> 99899.266 | C8: =C7*(1+MAX(($Q$2-30)*0.0001+0.0001+$R$2,0))+K7*IF(M7=0,1,L7/M7) -> 3228.9214 | D8: =D7*(1+MAX(($Q$2-30)*0.0001+0.0001+$R$2,0))+K7*IF(L7=0,1,M7/L7) -> 65.896356 | E8: =C8/B8 -> 0.032321773 | F8: =D8/B8 -> 0.00065962803 | G8: 0.01 | H8: =MIN((D8/B8)/(0.01+(J8*0.001))+I8,1) -> 0.4659628 | I8: 0.4 | J8: 0 | K8: =B8/500/4*(0.3-IF($N$2="Yes",0.1,0)+VLOOKUP(G8,$V$3:$W$11,2,TRUE()))*H8*12 -> 83.788816 | L8: =(VLOOKUP(G8,$T$15:$U$21,2,1)+VLOOKUP($O$2,$T$26:$U$36,2,1)-0.12)*IF(E8>0.041,0,1) -> 0.14 | M8: =VLOOKUP(G8,$X$15:$Y$22,2,1)+VLOOKUP($P$2,$X$26:$Y$37,2,1)*IF(F8>0.04,0,1) -> 0.02 | V8: 0.51 | W8: =SUM(X3:X8) -> 0.117 | X8: 0.021
A9: 1837 | B9: =B8*(1+MAX(($Q$2-30)*0.0001+0.0001+$R$2,0))-K8 -> 99875.417 | C9: =C8*(1+MAX(($Q$2-30)*0.0001+0.0001+$R$2,0))+K8*IF(M8=0,1,L8/M8) -> 3817.3805 | D9: =D8*(1+MAX(($Q$2-30)*0.0001+0.0001+$R$2,0))+K8*IF(L8=0,1,M8/L8) -> 77.905724 | E9: =C9/B9 -> 0.038221422 | F9: =D9/B9 -> 0.00078002903 | G9: 0.01 | H9: =MIN((D9/B9)/(0.01+(J9*0.001))+I9,1) -> 0.4780029 | I9: 0.4 | J9: 0 | K9: =B9/500/4*(0.3-IF($N$2="Yes",0.1,0)+VLOOKUP(G9,$V$3:$W$11,2,TRUE()))*H9*12 -> 85.93333 | L9: =(VLOOKUP(G9,$T$15:$U$21,2,1)+VLOOKUP($O$2,$T$26:$U$36,2,1)-0.12)*IF(E9>0.041,0,1) -> 0.14 | M9: =VLOOKUP(G9,$X$15:$Y$22,2,1)+VLOOKUP($P$2,$X$26:$Y$37,2,1)*IF(F9>0.04,0,1) -> 0.02 | V9: 0.62 | W9: =SUM(X3:X9) -> 0.139 | X9: 0.022
A10: 1838 | B10: =B9*(1+MAX(($Q$2-30)*0.0001+0.0001+$R$2,0))-K9 -> 99849.409 | C10: =C9*(1+MAX(($Q$2-30)*0.0001+0.0001+$R$2,0))+K9*IF(M9=0,1,L9/M9) -> 4421.2042 | D10: =D9*(1+MAX(($Q$2-30)*0.0001+0.0001+$R$2,0))+K9*IF(L9=0,1,M9/L9) -> 90.228658 | E10: =C10/B10 -> 0.044278722 | F10: =D10/B10 -> 0.00090364739 | G10: 0.01 | H10: =MIN((D10/B10)/(0.01+(J10*0.001))+I10,1) -> 0.49036474 | I10: 0.4 | J10: 0 | K10: =B10/500/4*(0.3-IF($N$2="Yes",0.1,0)+VLOOKUP(G10,$V$3:$W$11,2,TRUE()))*H10*12 -> 88.132733 | L10: =(VLOOKUP(G10,$T$15:$U$21,2,1)+VLOOKUP($O$2,$T$26:$U$36,2,1)-0.12)*IF(E10>0.041,0,1) -> 0 | M10: =VLOOKUP(G10,$X$15:$Y$22,2,1)+VLOOKUP($P$2,$X$26:$Y$37,2,1)*IF(F10>0.04,0,1) -> 0.02 | V10: 0.75 | W10: =SUM(X3:X10) -> 0.162 | X10: 0.023
A11: 1839 | B11: =B10*(1+MAX(($Q$2-30)*0.0001+0.0001+$R$2,0))-K10 -> 99821.186 | C11: =C10*(1+MAX(($Q$2-30)*0.0001+0.0001+$R$2,0))+K10*IF(M10=0,1,L10/M10) -> 4423.857 | D11: =D10*(1+MAX(($Q$2-30)*0.0001+0.0001+$R$2,0))+K10*IF(L10=0,1,M10/L10) -> 178.41553 | E11: =C11/B11 -> 0.044317816 | F11: =D11/B11 -> 0.0017873513 | G11: 0.01 | H11: =MIN((D11/B11)/(0.01+(J11*0.001))+I11,1) -> 0.57873513 | I11: 0.4 | J11: 0 | K11: =B11/500/4*(0.3-IF($N$2="Yes",0.1,0)+VLOOKUP(G11,$V$3:$W$11,2,TRUE()))*H11*12 -> 103.98605 | L11: =(VLOOKUP(G11,$T$15:$U$21,2,1)+VLOOKUP($O$2,$T$26:$U$36,2,1)-0.12)*IF(E11>0.041,0,1) -> 0 | M11: =VLOOKUP(G11,$X$15:$Y$22,2,1)+VLOOKUP($P$2,$X$26:$Y$37,2,1)*IF(F11>0.04,0,1) -> 0.02 | V11: 0.9 | W11: =SUM(X3:X11) -> 0.186 | X11: 0.024
A12: 1840 | B12: =B11*(1+MAX(($Q$2-30)*0.0001+0.0001+$R$2,0))-K11 -> 99777.092 | C12: =C11*(1+MAX(($Q$2-30)*0.0001+0.0001+$R$2,0))+K11*IF(M11=0,1,L11/M11) -> 4426.5113 | D12: =D11*(1+MAX(($Q$2-30)*0.0001+0.0001+$R$2,0))+K11*IF(L11=0,1,M11/L11) -> 282.50863 | E12: =C12/B12 -> 0.044364004 | F12: =D12/B12 -> 0.0028313977 | G12: 0.01 | H12: =MIN((D12/B12)/(0.01+(J12*0.001))+I12,1) -> 0.68313977 | I12: 0.4 | J12: 0 | K12: =B12/500/4*(0.3-IF($N$2="Yes",0.1,0)+VLOOKUP(G12,$V$3:$W$11,2,TRUE()))*H12*12 -> 122.69106 | L12: =(VLOOKUP(G12,$T$15:$U$21,2,1)+VLOOKUP($O$2,$T$26:$U$36,2,1)-0.12)*IF(E12>0.041,0,1) -> 0 | M12: =VLOOKUP(G12,$X$15:$Y$22,2,1)+VLOOKUP($P$2,$X$26:$Y$37,2,1)*IF(F12>0.04,0,1) -> 0.02
A13: 1841 | B13: =B12*(1+MAX(($Q$2-30)*0.0001+0.0001+$R$2,0))-K12 -> 99714.267 | C13: =C12*(1+MAX(($Q$2-30)*0.0001+0.0001+$R$2,0))+K12*IF(M12=0,1,L12/M12) -> 4429.1672 | D13: =D12*(1+MAX(($Q$2-30)*0.0001+0.0001+$R$2,0))+K12*IF(L12=0,1,M12/L12) -> 405.36919 | E13: =C13/B13 -> 0.04441859 | F13: =D13/B13 -> 0.0040653078 | G13: 0.01 | H13: =MIN((D13/B13)/(0.01+(J13*0.001))+I13,1) -> 0.80653078 | I13: 0.4 | J13: 0 | K13: =B13/500/4*(0.3-IF($N$2="Yes",0.1,0)+VLOOKUP(G13,$V$3:$W$11,2,TRUE()))*H13*12 -> 144.76073 | L13: =(VLOOKUP(G13,$T$15:$U$21,2,1)+VLOOKUP($O$2,$T$26:$U$36,2,1)-0.12)*IF(E13>0.041,0,1) -> 0 | M13: =VLOOKUP(G13,$X$15:$Y$22,2,1)+VLOOKUP($P$2,$X$26:$Y$37,2,1)*IF(F13>0.04,0,1) -> 0.02 | T13: Promotion - Intellectualists | X13: Promotion – Bureaucrats
A14: 1842 | B14: =B13*(1+MAX(($Q$2-30)*0.0001+0.0001+$R$2,0))-K13 -> 99629.335 | C14: =C13*(1+MAX(($Q$2-30)*0.0001+0.0001+$R$2,0))+K13*IF(M13=0,1,L13/M13) -> 4431.8247 | D14: =D13*(1+MAX(($Q$2-30)*0.0001+0.0001+$R$2,0))+K13*IF(L13=0,1,M13/L13) -> 550.37314 | E14: =C14/B14 -> 0.04448313 | F14: =D14/B14 -> 0.0055242077 | G14: 0.01 | H14: =MIN((D14/B14)/(0.01+(J14*0.001))+I14,1) -> 0.95242077 | I14: 0.4 | J14: 0 | K14: =B14/500/4*(0.3-IF($N$2="Yes",0.1,0)+VLOOKUP(G14,$V$3:$W$11,2,TRUE()))*H14*12 -> 170.80029 | L14: =(VLOOKUP(G14,$T$15:$U$21,2,1)+VLOOKUP($O$2,$T$26:$U$36,2,1)-0.12)*IF(E14>0.041,0,1) -> 0 | M14: =VLOOKUP(G14,$X$15:$Y$22,2,1)+VLOOKUP($P$2,$X$26:$Y$37,2,1)*IF(F14>0.04,0,1) -> 0.02 | T14: Literacy | U14: Total Bonus | V14: Bonus | X14: Literacy | Y14: Total Bonus | Z14: Bonus
A15: 1843 | B15: =B14*(1+MAX(($Q$2-30)*0.0001+0.0001+$R$2,0))-K14 -> 99518.313 | C15: =C14*(1+MAX(($Q$2-30)*0.0001+0.0001+$R$2,0))+K14*IF(M14=0,1,L14/M14) -> 4434.4838 | D15: =D14*(1+MAX(($Q$2-30)*0.0001+0.0001+$R$2,0))+K14*IF(L14=0,1,M14/L14) -> 721.50365 | E15: =C15/B15 -> 0.044559475 | F15: =D15/B15 -> 0.0072499586 | G15: 0.01 | H15: =MIN((D15/B15)/(0.01+(J15*0.001))+I15,1) -> 1 | I15: 0.4 | J15: 0 | K15: =B15/500/4*(0.3-IF($N$2="Yes",0.1,0)+VLOOKUP(G15,$V$3:$W$11,2,TRUE()))*H15*12 -> 179.13296 | L15: =(VLOOKUP(G15,$T$15:$U$21,2,1)+VLOOKUP($O$2,$T$26:$U$36,2,1)-0.12)*IF(E15>0.041,0,1) -> 0 | M15: =VLOOKUP(G15,$X$15:$Y$22,2,1)+VLOOKUP($P$2,$X$26:$Y$37,2,1)*IF(F15>0.04,0,1) -> 0.02 | T15: 0 | U15: =SUM(V15) -> 0 | V15: 0 | X15: 0 | Y15: =SUM(Z15) -> 0 | Z15: 0
A16: 1844 | B16: =B15*(1+MAX(($Q$2-30)*0.0001+0.0001+$R$2,0))-K15 -> 99398.891 | C16: =C15*(1+MAX(($Q$2-30)*0.0001+0.0001+$R$2,0))+K15*IF(M15=0,1,L15/M15) -> 4437.1445 | D16: =D15*(1+MAX(($Q$2-30)*0.0001+0.0001+$R$2,0))+K15*IF(L15=0,1,M15/L15) -> 901.06951 | E16: =C16/B16 -> 0.044639779 | F16: =D16/B16 -> 0.0090651868 | G16: 0.01 | H16: =MIN((D16/B16)/(0.01+(J16*0.001))+I16,1) -> 1 | I16: 0.4 | J16: 0 | K16: =B16/500/4*(0.3-IF($N$2="Yes",0.1,0)+VLOOKUP(G16,$V$3:$W$11,2,TRUE()))*H16*12 -> 178.918 | L16: =(VLOOKUP(G16,$T$15:$U$21,2,1)+VLOOKUP($O$2,$T$26:$U$36,2,1)-0.12)*IF(E16>0.041,0,1) -> 0 | M16: =VLOOKUP(G16,$X$15:$Y$22,2,1)+VLOOKUP($P$2,$X$26:$Y$37,2,1)*IF(F16>0.04,0,1) -> 0.02 | T16: 0.3 | U16: =SUM(V15:V16) -> 0.005 | V16: 0.005 | X16: 0.4 | Y16: =SUM(Z15:Z16) -> 0.0025 | Z16: 0.0025
A17: 1845 | B17: =B16*(1+MAX(($Q$2-30)*0.0001+0.0001+$R$2,0))-K16 -> 99279.612 | C17: =C16*(1+MAX(($Q$2-30)*0.0001+0.0001+$R$2,0))+K16*IF(M16=0,1,L16/M16) -> 4439.8067 | D17: =D16*(1+MAX(($Q$2-30)*0.0001+0.0001+$R$2,0))+K16*IF(L16=0,1,M16/L16) -> 1080.5282 | E17: =C17/B17 -> 0.044720227 | F17: =D17/B17 -> 0.010883686 | G17: 0.01 | H17: =MIN((D17/B17)/(0.01+(J17*0.001))+I17,1) -> 1 | I17: 0.4 | J17: 0 | K17: =B17/500/4*(0.3-IF($N$2="Yes",0.1,0)+VLOOKUP(G17,$V$3:$W$11,2,TRUE()))*H17*12 -> 178.7033 | L17: =(VLOOKUP(G17,$T$15:$U$21,2,1)+VLOOKUP($O$2,$T$26:$U$36,2,1)-0.12)*IF(E17>0.041,0,1) -> 0 | M17: =VLOOKUP(G17,$X$15:$Y$22,2,1)+VLOOKUP($P$2,$X$26:$Y$37,2,1)*IF(F17>0.04,0,1) -> 0.02 | T17: 0.4 | U17: =SUM(V15:V17) -> 0.0075 | V17: 0.0025 | X17: 0.5 | Y17: =SUM(Z15:Z17) -> 0.005 | Z17: 0.0025
A18: 1846 | B18: =B17*(1+MAX(($Q$2-30)*0.0001+0.0001+$R$2,0))-K17 -> 99160.476 | C18: =C17*(1+MAX(($Q$2-30)*0.0001+0.0001+$R$2,0))+K17*IF(M17=0,1,L17/M17) -> 4442.4706 | D18: =D17*(1+MAX(($Q$2-30)*0.0001+0.0001+$R$2,0))+K17*IF(L17=0,1,M17/L17) -> 1259.8798 | E18: =C18/B18 -> 0.04480082 | F18: =D18/B18 -> 0.012705463 | G18: 0.01 | H18: =MIN((D18/B18)/(0.01+(J18*0.001))+I18,1) -> 1 | I18: 0.4 | J18: 0 | K18: =B18/500/4*(0.3-IF($N$2="Yes",0.1,0)+VLOOKUP(G18,$V$3:$W$11,2,TRUE()))*H18*12 -> 178.48886 | L18: =(VLOOKUP(G18,$T$15:$U$21,2,1)+VLOOKUP($O$2,$T$26:$U$36,2,1)-0.12)*IF(E18>0.041,0,1) -> 0 | M18: =VLOOKUP(G18,$X$15:$Y$22,2,1)+VLOOKUP($P$2,$X$26:$Y$37,2,1)*IF(F18>0.04,0,1) -> 0.02 | T18: 0.5 | U18: =SUM(V15:V18) -> 0.01 | V18: 0.0025 | X18: 0.6 | Y18: =SUM(Z15:Z18) -> 0.01 | Z18: 0.005
A19: 1847 | B19: =B18*(1+MAX(($Q$2-30)*0.0001+0.0001+$R$2,0))-K18 -> 99041.484 | C19: =C18*(1+MAX(($Q$2-30)*0.0001+0.0001+$R$2,0))+K18*IF(M18=0,1,L18/M18) -> 4445.1361 | D19: =D18*(1+MAX(($Q$2-30)*0.0001+0.0001+$R$2,0))+K18*IF(L18=0,1,M18/L18) -> 1439.1246 | E19: =C19/B19 -> 0.044881558 | F19: =D19/B19 -> 0.014530523 | G19: 0.01 | H19: =MIN((D19/B19)/(0.01+(J19*0.001))+I19,1) -> 1 | I19: 0.4 | J19: 0 | K19: =B19/500/4*(0.3-IF($N$2="Yes",0.1,0)+VLOOKUP(G19,$V$3:$W$11,2,TRUE()))*H19*12 -> 178.27467 | L19: =(VLOOKUP(G19,$T$15:$U$21,2,1)+VLOOKUP($O$2,$T$26:$U$36,2,1)-0.12)*IF(E19>0.041,0,1) -> 0 | M19: =VLOOKUP(G19,$X$15:$Y$22,2,1)+VLOOKUP($P$2,$X$26:$Y$37,2,1)*IF(F19>0.04,0,1) -> 0.02 | T19: 0.6 | U19: =SUM(V15:V19) -> 0.0125 | V19: 0.0025 | X19: 0.7 | Y19: =SUM(Z15:Z19) -> 0.015 | Z19: 0.005
A20: 1848 | B20: =B19*(1+MAX(($Q$2-30)*0.0001+0.0001+$R$2,0))-K19 -> 98922.634 | C20: =C19*(1+MAX(($Q$2-30)*0.0001+0.0001+$R$2,0))+K19*IF(M19=0,1,L19/M19) -> 4447.8032 | D20: =D19*(1+MAX(($Q$2-30)*0.0001+0.0001+$R$2,0))+K19*IF(L19=0,1,M19/L19) -> 1618.2627 | E20: =C20/B20 -> 0.044962442 | F20: =D20/B20 -> 0.016358872 | G20: 0.01 | H20: =MIN((D20/B20)/(0.01+(J20*0.001))+I20,1) -> 1 | I20: 0.4 | J20: 0 | K20: =B20/500/4*(0.3-IF($N$2="Yes",0.1,0)+VLOOKUP(G20,$V$3:$W$11,2,TRUE()))*H20*12 -> 178.06074 | L20: =(VLOOKUP(G20,$T$15:$U$21,2,1)+VLOOKUP($O$2,$T$26:$U$36,2,1)-0.12)*IF(E20>0.041,0,1) -> 0 | M20: =VLOOKUP(G20,$X$15:$Y$22,2,1)+VLOOKUP($P$2,$X$26:$Y$37,2,1)*IF(F20>0.04,0,1) -> 0.02 | T20: 0.7 | U20: =SUM(V15:V20) -> 0.015 | V20: 0.0025 | X20: 0.8 | Y20: =SUM(Z15:Z20) -> 0.025 | Z20: 0.01
A21: 1849 | B21: =B20*(1+MAX(($Q$2-30)*0.0001+0.0001+$R$2,0))-K20 -> 98803.927 | C21: =C20*(1+MAX(($Q$2-30)*0.0001+0.0001+$R$2,0))+K20*IF(M20=0,1,L20/M20) -> 4450.4719 | D21: =D20*(1+MAX(($Q$2-30)*0.0001+0.0001+$R$2,0))+K20*IF(L20=0,1,M20/L20) -> 1797.2944 | E21: =C21/B21 -> 0.045043472 | F21: =D21/B21 -> 0.018190516 | G21: 0.01 | H21: =MIN((D21/B21)/(0.01+(J21*0.001))+I21,1) -> 1 | I21: 0.4 | J21: 0 | K21: =B21/500/4*(0.3-IF($N$2="Yes",0.1,0)+VLOOKUP(G21,$V$3:$W$11,2,TRUE()))*H21*12 -> 177.84707 | L21: =(VLOOKUP(G21,$T$15:$U$21,2,1)+VLOOKUP($O$2,$T$26:$U$36,2,1)-0.12)*IF(E21>0.041,0,1) -> 0 | M21: =VLOOKUP(G21,$X$15:$Y$22,2,1)+VLOOKUP($P$2,$X$26:$Y$37,2,1)*IF(F21>0.04,0,1) -> 0.02 | T21: 0.8 | U21: =SUM(V15:V21) -> 0.0175 | V21: 0.0025 | X21: 0.9 | Y21: =SUM(Z15:Z21) -> 0.035 | Z21: 0.01
A22: 1850 | B22: =B21*(1+MAX(($Q$2-30)*0.0001+0.0001+$R$2,0))-K21 -> 98685.362 | C22: =C21*(1+MAX(($Q$2-30)*0.0001+0.0001+$R$2,0))+K21*IF(M21=0,1,L21/M21) -> 4453.1422 | D22: =D21*(1+MAX(($Q$2-30)*0.0001+0.0001+$R$2,0))+K21*IF(L21=0,1,M21/L21) -> 1976.2199 | E22: =C22/B22 -> 0.045124647 | F22: =D22/B22 -> 0.020025461 | G22: 0.01 | H22: =MIN((D22/B22)/(0.01+(J22*0.001))+I22,1) -> 1 | I22: 0.4 | J22: 0 | K22: =B22/500/4*(0.3-IF($N$2="Yes",0.1,0)+VLOOKUP(G22,$V$3:$W$11,2,TRUE()))*H22*12 -> 177.63365 | L22: =(VLOOKUP(G22,$T$15:$U$21,2,1)+VLOOKUP($O$2,$T$26:$U$36,2,1)-0.12)*IF(E22>0.041,0,1) -> 0 | M22: =VLOOKUP(G22,$X$15:$Y$22,2,1)+VLOOKUP($P$2,$X$26:$Y$37,2,1)*IF(F22>0.04,0,1) -> 0.02 | X22: 1 | Y22: =SUM(Z15:Z22) -> 0.055 | Z22: 0.02
T24: Intellectualists - MONEY | X24: Bureaucrats - MONEY
T25: Cash | U25: Total Bonus | V25: Bonus | X25: Cash | Y25: Total Bonus | Z25: Bonus
T26: 0 | U26: =SUM(V26) -> 0 | V26: 0 | X26: 0 | Y26: =SUM(Z26) -> 0 | Z26: 0
T27: 0.1 | U27: =SUM(V26:V27) -> 0.02 | V27: 0.02 | X27: 0.1 | Y27: =SUM(Z26:Z27) -> 0.02 | Z27: 0.02
T28: 0.2 | U28: =SUM(V26:V28) -> 0.04 | V28: 0.02 | X28: 0.2 | Y28: =SUM(Z26:Z28) -> 0.04 | Z28: 0.02
T29: 0.3 | U29: =SUM(V26:V29) -> 0.06 | V29: 0.02 | X29: 0.3 | Y29: =SUM(Z26:Z29) -> 0.06 | Z29: 0.02
T30: 0.4 | U30: =SUM(V26:V30) -> 0.082 | V30: 0.022 | X30: 0.4 | Y30: =SUM(Z26:Z30) -> 0.08 | Z30: 0.02
T31: 0.5 | U31: =SUM(V26:V31) -> 0.105 | V31: 0.023 | X31: 0.5 | Y31: =SUM(Z26:Z31) -> 0.1 | Z31: 0.02
T32: 0.6 | U32: =SUM(V26:V32) -> 0.13 | V32: 0.025 | X32: 0.6 | Y32: =SUM(Z26:Z32) -> 0.12 | Z32: 0.02
T33: 0.75 | U33: =SUM(V26:V33) -> 0.2 | V33: 0.07 | X33: 0.7 | Y33: =SUM(Z26:Z33) -> 0.14 | Z33: 0.02
T34: 0.8 | U34: =SUM(V26:V34) -> 0.22 | V34: 0.02 | X34: 0.75 | Y34: =SUM(Z26:Z34) -> 0.2 | Z34: 0.06
T35: 0.9 | U35: =SUM(V26:V35) -> 0.24 | V35: 0.02 | X35: 0.8 | Y35: =SUM(Z26:Z35) -> 0.22 | Z35: 0.02
T36: 1 | U36: =SUM(V26:V36) -> 0.26 | V36: 0.02 | X36: 0.9 | Y36: =SUM(Z26:Z36) -> 0.24 | Z36: 0.02
X37: 1 | Y37: =SUM(Z27:Z37) -> 0.26 | Z37: 0.02

Sheet Treaty Ports
A1: Treaty Port | B1: POPs | C1: Provinces in state | D1: Terrain | E1: Infrastructure | F1: Naval Base | G1: Life Rating | H1: Output | I1: Base Income | K1: Max Infrastructure | L1: Good Output | M1: Admin Efficiency | N1: Tax Efficiency | O1: Date
A2: Ningpo | B2: =249000 -> 249000 | C2: 1 | D2: 0 | E2: -1 | F2: 2 | G2: 32 | H2: =B2/40000*'Goods values'!$B$3*(1+D2+$L$2+MAX(($K$2+E2)*0.16,0)) -> 43.326 | I2: =H2*'Goods values'!$C$3*3*MAX($M$2-(C2*0.075),0)*$N$2+H2 -> 133.40075 | K2: 3 | L2: 1 | M2: 0.35 | N2: 0.14 | O2: 1830
A3: Shanghai | B3: 188250 | C3: 1 | D3: 0 | E3: -1 | F3: 6 | G3: 32 | H3: =B3/40000*'Goods values'!$B$3*(1+D3+$L$2+MAX(($K$2+E3)*0.16,0)) -> 32.7555 | I3: =H3*'Goods values'!$C$3*3*MAX($M$2-(C3*0.075),0)*$N$2+H3 -> 100.85418
A4: Kashing | B4: 78300 | C4: 1 | D4: 0 | E4: -1 | F4: 2 | G4: 32 | H4: =B4/40000*'Goods values'!$B$3*(1+D4+$L$2+MAX(($K$2+E4)*0.16,0)) -> 13.6242 | I4: =H4*'Goods values'!$C$3*3*MAX($M$2-(C4*0.075),0)*$N$2+H4 -> 41.948912
A5: Sanmen | B5: 83125 | C5: 1 | D5: 0 | E5: -2 | F5: 6 | G5: 32 | H5: =B5/40000*'Goods values'!$B$3*(1+D5+$L$2+MAX(($K$2+E5)*0.16,0)) -> 13.46625 | I5: =H5*'Goods values'!$C$3*3*MAX($M$2-(C5*0.075),0)*$N$2+H5 -> 41.462584
A6: Cheju | B6: =53731+10486 -> 64217 | C6: 1 | D6: 0 | E6: -2 | F6: 6 | G6: 30 | H6: =B6/40000*'Goods values'!$B$3*(1+D6+$L$2+MAX(($K$2+E6)*0.16,0)) -> 10.403154 | I6: =H6*'Goods values'!$C$3*3*MAX($M$2-(C6*0.075),0)*$N$2+H6 -> 32.031311
A7: Zanzibar | B7: =23725+19000 -> 42725 | C7: 1 | D7: 0 | E7: -2 | F7: 6 | G7: 40 | H7: =B7/40000*'Goods values'!$B$3*(1+D7+$L$2+MAX(($K$2+E7)*0.16,0)) -> 6.92145 | I7: =H7*'Goods values'!$C$3*3*MAX($M$2-(C7*0.075),0)*$N$2+H7 -> 21.311145
A8: Old Tientsin | B8: 34540 | C8: 1 | D8: 0 | E8: 0 | F8: 6 | G8: 32 | H8: =B8/40000*'Goods values'!$B$3*(1+D8+$L$2+MAX(($K$2+E8)*0.16,0)) -> 6.42444 | I8: =H8*'Goods values'!$C$3*3*MAX($M$2-(C8*0.075),0)*$N$2+H8 -> 19.780851
A9: Kwangchowan | B9: 25000 | C9: 1 | D9: 0 | E9: -1 | F9: 3 | G9: 32 | H9: =B9/40000*'Goods values'!$B$3*(1+D9+$L$2+MAX(($K$2+E9)*0.16,0)) -> 4.35 | I9: =H9*'Goods values'!$C$3*3*MAX($M$2-(C9*0.075),0)*$N$2+H9 -> 13.39365
A10: Lushun | B10: 22231 | C10: 1 | D10: 0 | E10: 0 | F10: 6 | G10: 32 | H10: =B10/40000*'Goods values'!$B$3*(1+D10+$L$2+MAX(($K$2+E10)*0.16,0)) -> 4.134966 | I10: =H10*'Goods values'!$C$3*3*MAX($M$2-(C10*0.075),0)*$N$2+H10 -> 12.73156
A11: Muqdisho | B11: =14800+5500 -> 20300 | C11: 1 | D11: 0 | E11: -1 | F11: 6 | G11: 35 | H11: =B11/40000*'Goods values'!$B$3*(1+D11+$L$2+MAX(($K$2+E11)*0.16,0)) -> 3.5322 | I11: =H11*'Goods values'!$C$3*3*MAX($M$2-(C11*0.075),0)*$N$2+H11 -> 10.875644
A12: Sado | B12: =18400+1750 -> 20150 | C12: 1 | D12: 0 | E12: -2 | F12: 6 | G12: 30 | H12: =B12/40000*'Goods values'!$B$3*(1+D12+$L$2+MAX(($K$2+E12)*0.16,0)) -> 3.2643 | I12: =H12*'Goods values'!$C$3*3*MAX($M$2-(C12*0.075),0)*$N$2+H12 -> 10.05078
A13: Chusan Islands | B13: 12150 | C13: 1 | D13: 0 | E13: -2 | F13: 2 | G13: 32 | H13: =B13/40000*'Goods values'!$B$3*(1+D13+$L$2+MAX(($K$2+E13)*0.16,0)) -> 1.9683 | I13: =H13*'Goods values'!$C$3*3*MAX($M$2-(C13*0.075),0)*$N$2+H13 -> 6.0603957
A14: Macao | B14: =6580+450 -> 7030 | C14: 1 | D14: 0.25 | E14: 0 | F14: 3 | G14: 35 | H14: =B14/40000*'Goods values'!$B$3*(1+D14+$L$2+MAX(($K$2+E14)*0.16,0)) -> 1.4393925 | I14: =H14*'Goods values'!$C$3*3*MAX($M$2-(C14*0.075),0)*$N$2+H14 -> 4.4318895
A15: Socotra | B15: 7562 | C15: 1 | D15: 0 | E15: -2 | F15: 6 | G15: 20 | H15: =B15/40000*'Goods values'!$B$3*(1+D15+$L$2+MAX(($K$2+E15)*0.16,0)) -> 1.225044 | I15: =H15*'Goods values'!$C$3*3*MAX($M$2-(C15*0.075),0)*$N$2+H15 -> 3.7719105
A16: Weihaiwei | B16: 6375 | C16: 1 | D16: 0 | E16: 0 | F16: 6 | G16: 32 | H16: =B16/40000*'Goods values'!$B$3*(1+D16+$L$2+MAX(($K$2+E16)*0.16,0)) -> 1.18575 | I16: =H16*'Goods values'!$C$3*3*MAX($M$2-(C16*0.075),0)*$N$2+H16 -> 3.6509243
A17: Tsingtao | B17: 5475 | C17: 1 | D17: 0 | E17: 0 | F17: 6 | G17: 32 | H17: =B17/40000*'Goods values'!$B$3*(1+D17+$L$2+MAX(($K$2+E17)*0.16,0)) -> 1.01835 | I17: =H17*'Goods values'!$C$3*3*MAX($M$2-(C17*0.075),0)*$N$2+H17 -> 3.1354996
A18: Brunei | B18: =5375+500 -> 5875 | C18: 1 | D18: 0 | E18: -3 | F18: 6 | G18: 31 | H18: =B18/40000*'Goods values'!$B$3*(1+D18+$L$2+MAX(($K$2+E18)*0.16,0)) -> 0.88125 | I18: =H18*'Goods values'!$C$3*3*MAX($M$2-(C18*0.075),0)*$N$2+H18 -> 2.7133687
A19: Barbara | B19: 5000 | C19: 1 | D19: 0 | E19: -2 | F19: 6 | G19: 31 | H19: =B19/40000*'Goods values'!$B$3*(1+D19+$L$2+MAX(($K$2+E19)*0.16,0)) -> 0.81 | I19: =H19*'Goods values'!$C$3*3*MAX($M$2-(C19*0.075),0)*$N$2+H19 -> 2.49399
A20: Sidi Infi | B20: 4325 | C20: 1 | D20: 0 | E20: -3 | F20: 6 | G20: 30 | H20: =B20/40000*'Goods values'!$B$3*(1+D20+$L$2+MAX(($K$2+E20)*0.16,0)) -> 0.64875 | I20: =H20*'Goods values'!$C$3*3*MAX($M$2-(C20*0.075),0)*$N$2+H20 -> 1.9975013
A21: Hong Kong | B21: 2750 | C21: 1 | D21: 0.25 | E21: 0 | F21: 3 | G21: 32 | H21: =B21/40000*'Goods values'!$B$3*(1+D21+$L$2+MAX(($K$2+E21)*0.16,0)) -> 0.5630625 | I21: =H21*'Goods values'!$C$3*3*MAX($M$2-(C21*0.075),0)*$N$2+H21 -> 1.7336694
A22: Tsushima | B22: 3263 | C22: 1 | D22: 0 | E22: -2 | F22: 6 | G22: 31 | H22: =B22/40000*'Goods values'!$B$3*(1+D22+$L$2+MAX(($K$2+E22)*0.16,0)) -> 0.528606 | I22: =H22*'Goods values'!$C$3*3*MAX($M$2-(C22*0.075),0)*$N$2+H22 -> 1.6275779
A23: Oki Islands | B23: 1950 | C23: 1 | D23: 0 | E23: -2 | F23: 6 | G23: 35 | H23: =B23/40000*'Goods values'!$B$3*(1+D23+$L$2+MAX(($K$2+E23)*0.16,0)) -> 0.3159 | I23: =H23*'Goods values'!$C$3*3*MAX($M$2-(C23*0.075),0)*$N$2+H23 -> 0.9726561
A24: Gwadar | B24: =1250+200 -> 1450 | C24: 1 | D24: 0 | E24: -2 | F24: 6 | G24: 35 | H24: =B24/40000*'Goods values'!$B$3*(1+D24+$L$2+MAX(($K$2+E24)*0.16,0)) -> 0.2349 | I24: =H24*'Goods values'!$C$3*3*MAX($M$2-(C24*0.075),0)*$N$2+H24 -> 0.7232571
A25: Qeshm | B25: 1250 | C25: 1 | D25: 0 | E25: -2 | F25: 6 | G25: 35 | H25: =B25/40000*'Goods values'!$B$3*(1+D25+$L$2+MAX(($K$2+E25)*0.16,0)) -> 0.2025 | I25: =H25*'Goods values'!$C$3*3*MAX($M$2-(C25*0.075),0)*$N$2+H25 -> 0.6234975
A26: Tarfaya | B26: 555 | C26: 1 | D26: 0.25 | E26: 0 | F26: 6 | G26: 15 | H26: =B26/40000*'Goods values'!$B$3*(1+D26+$L$2+MAX(($K$2+E26)*0.16,0)) -> 0.11363625 | I26: =H26*'Goods values'!$C$3*3*MAX($M$2-(C26*0.075),0)*$N$2+H26 -> 0.34988601
A27: Juzur Khuriya Muriya | B27: 35 | C27: 1 | D27: 0 | E27: -2 | F27: 6 | G27: 10 | H27: =B27/40000*'Goods values'!$B$3*(1+D27+$L$2+MAX(($K$2+E27)*0.16,0)) -> 0.00567 | I27: =H27*'Goods values'!$C$3*3*MAX($M$2-(C27*0.075),0)*$N$2+H27 -> 0.01745793
A29: Hainan | B29: =632620+146420 -> 779040 | C29: 1 | D29: 0 | E29: -3 | F29: 3 | H29: =B29/40000*'Goods values'!$B$3*(1+D29+MAX(($K$2+E29)*0.16,0)) -> 58.428 | I29: =H29*'Goods values'!$C$24*MAX($M$2-(C29*0.075),0)*$N$2 -> 3.374217
A30: al-Jazair | B30: 48171 | C30: 1 | D30: 0 | E30: 0 | F30: 6 | H30: =B30/40000*'Goods values'!$B$3*(1+D30+MAX(($K$2+E30)*0.16,0)) -> 5.346981 | I30: =H30*'Goods values'!$C$24*MAX($M$2-(C30*0.075),0)*$N$2 -> 0.30878815
A31: Wahran | B31: 42720 | C31: 1 | D31: 0 | E31: -2 | F31: 6 | H31: =B31/40000*'Goods values'!$B$3*(1+D31+MAX(($K$2+E31)*0.16,0)) -> 3.71664 | I31: =H31*'Goods values'!$C$24*MAX($M$2-(C31*0.075),0)*$N$2 -> 0.21463596
A32: Ennab | B32: 21165 | C32: 1 | D32: 0 | E32: -2 | F32: 3 | H32: =B32/40000*'Goods values'!$B$3*(1+D32+MAX(($K$2+E32)*0.16,0)) -> 1.841355 | I32: =H32*'Goods values'!$C$24*MAX($M$2-(C32*0.075),0)*$N$2 -> 0.10633825
A33: Bijaya | B33: 20505 | C33: 1 | D33: 0 | E33: -2 | F33: 3 | H33: =B33/40000*'Goods values'!$B$3*(1+D33+MAX(($K$2+E33)*0.16,0)) -> 1.783935 | I33: =H33*'Goods values'!$C$24*MAX($M$2-(C33*0.075),0)*$N$2 -> 0.10302225
A34: Taiwan | B34: =243850+397100+16000+41000 -> 697950 | C34: 5 | D34: 0.01 | E34: =-11/5 -> -2.2 | F34: 6 | H34: =B34/40000*'Goods values'!$B$3*(1+D34+MAX(($K$2+E34)*0.16,0)) -> 59.570033 | I34: =H34*'Goods values'!$C$24*MAX($M$2-(C34*0.075),0)*$N$2 -> 0

Sheet Goods values
A1: RGO Name | B1: Value | C1: Price | D1: Price per boi | F1: Date | G1: £ Output | H1: Farming Output | I1: Mining Output | J1: Goods Output | K1: Goods Throughput | L1: Railroad lvl | M1: Terrain Modifier
A2: Gold | B2: 3 | C2: 20 | D2: =B2*C2*3 -> 180 | F2: Bida | G2: =$D$3*(1+I2+J2+(L2*0.16)+$M$2)*(1+K2) -> 162 | I2: 0 | J2: 0 | K2: 0 | L2: 0 | M2: 0
A3: Precious Goods | B3: 3 | C3: 18 | D3: =B3*C3*3 -> 162 | F3: Base | G3: =$D$3*(1+I3+J3+(L3*0.16)+$M$2)*(1+K3) -> 309.42 | I3: 0.65 | J3: 0.1 | K3: 0 | L3: 1
A4: Gems | B4: 3 | C4: 18 | D4: =B4*C4*3 -> 162 | F4: 1830 | G4: =$D$3*(1+I4+J4+(L4*0.16)+$M$2)*(1+K4) -> 447.12 | I4: 1.05 | J4: 0.55 | K4: 0 | L4: 1
A5: Pearls | B5: 3 | C5: 18 | D5: =B5*C5*3 -> 162 | F5: 1840 | G5: =$D$3*(1+I5+J5+(L5*0.16)+$M$2)*(1+K5) -> 473.04 | I5: 1.05 | J5: 0.55 | K5: 0 | L5: 2
A6: Mercury | B6: 3 | C6: 18 | D6: =B6*C6*3 -> 162 | F6: 1850 | G6: =$D$3*(1+I6+J6+(L6*0.16)+$M$2)*(1+K6) -> 563.76 | I6: 1.2 | J6: 0.8 | K6: 0 | L6: 3
A7: Precious Metal | B7: 2.25 | C7: 20 | D7: =B7*C7*3 -> 135 | F7: 1870 | G7: =$D$3*(1+I7+J7+(L7*0.16)+$M$2)*(1+K7) -> 654.48 | I7: 1.2 | J7: 1.2 | K7: 0 | L7: 4
A8: Slave Trade | B8: 3 | C8: 13 | D8: =B8*C8*3 -> 117 | F8: 1880 | G8: =$D$3*(1+I8+J8+(L8*0.16)+$M$2)*(1+K8) -> 678.78 | I8: 1.35 | J8: 1.2 | K8: 0 | L8: 4
A9: Ivory | B9: 3 | C9: 10 | D9: =B9*C9*3 -> 90 | F9: 1898 | G9: =$D$3*(1+I9+J9+(L9*0.16)+$M$2)*(1+K9) -> 704.7 | I9: 1.35 | J9: 1.2 | K9: 0 | L9: 5
A10: Tropical Wood | B10: 4 | C10: 5.4 | D10: =B10*C10 -> 21.6 | F10: 1900 | G10: =$D$3*(1+I10+J10+(L10*0.16)+$M$2)*(1+K10) -> 907.2 | I10: 2.2 | J10: 1.6 | K10: 0 | L10: 5
A11: Sulphur | B11: 3 | C11: 6 | D11: =B11*C11 -> 18 | F11: 1915 | G11: =$D$3*(1+I11+J11+(L11*0.16)+$M$2)*(1+K11) -> 933.12 | I11: 2.2 | J11: 1.6 | K11: 0 | L11: 6
A12: Oil | B12: 1 | C12: 12 | D12: =B12*C12 -> 12
A13: Wood | B13: 8 | C13: 0.9 | D13: =B13*C13 -> 7.2
A14: Iron | B14: 2 | C14: 3.5 | D14: =B14*C14 -> 7
A15: Coal | B15: 2.4 | C15: 2.3 | D15: =B15*C15 -> 5.52
A16: Rubber | B16: 0.75 | C16: 7 | D16: =B16*C16 -> 5.25
A17: Fruit | B17: 2.7 | C17: 1.8 | D17: =B17*C17 -> 4.86
A18: Tea | B18: 1.75 | C18: 2.6 | D18: =B18*C18 -> 4.55
A19: Grain | B19: 1.7 | C19: 2.2 | D19: =B19*C19 -> 3.74
A20: Cotton | B20: 1.8 | C20: 2 | D20: =B20*C20 -> 3.6
A21: Cattle | B21: 1.7 | C21: 2 | D21: =B21*C21 -> 3.4
A22: Wool | B22: 4.8 | C22: 0.7 | D22: =B22*C22 -> 3.36
A23: Sugar | B23: 1 | C23: 3.2 | D23: =B23*C23 -> 3.2
... A29: Opium | B29: 0.7 | C29: 3.2 | D29: =B29*C29 -> 2.24

Sheet POP Growth
A1: Date | B1: POP | C1: POP Growth | E1: Life Rating | F1: Starting POP
A2: 1830 | B2: =F2 -> 452530 | C2: 0 | E2: 30 | F2: 452530
A3: 1831 | B3: =B2*(1+0.0001+MAX(($E$2-36),0)*0.0001+C2) -> 452575.25 | C3: 0
A4: 1832 | B4: =B3*(1+0.0001+MAX(($E$2-36),0)*0.0001+C3) -> 452620.51 | C4: 0
A5: 1833 | B5: =B4*(1+0.0001+MAX(($E$2-36),0)*0.0001+C4) -> 452665.77 | C5: 0
A6: 1834 | B6: =B5*(1+0.0001+MAX(($E$2-36),0)*0.0001+C5) -> 452711.04 | C6: 0.0001
A7: 1835 | B7: =B6*(1+0.0001+MAX(($E$2-36),0)*0.0001+C6) -> 452801.58 | C7: 0.0001
A8: 1836 | B8: =B7*(1+0.0001+MAX(($E$2-36),0)*0.0001+C7) -> 452892.14 | C8: 0.0002
A9: 1837 | B9: =B8*(1+0.0001+MAX(($E$2-36),0)*0.0001+C8) -> 453028.01 | C9: 0.0003
A10: 1838 | B10: =B9*(1+0.0001+MAX(($E$2-36),0)*0.0001+C9) -> 453209.22 | C10: 0.0004
A11: 1839 | B11: =B10*(1+0.0001+MAX(($E$2-36),0)*0.0001+C10) -> 453435.83 | C11: 0.0004
A12: 1840 | B12: =B11*(1+0.0001+MAX(($E$2-36),0)*0.0001+C11) -> 453662.54 | C12: 0.0005
A13: 1841 | B13: =B12*(1+0.0001+MAX(($E$2-36),0)*0.0001+C12) -> 453934.74 | C13: 0.0005
A14: 1842 | B14: =B13*(1+0.0001+MAX(($E$2-36),0)*0.0001+C13) -> 454207.1 | C14: 0.0005
... A108: 1936 | B108: =B107*(1+0.0001+MAX(($E$2-36),0)*0.0001+C107) -> 486058.11 | C108: 0.0008

Sheet Military
A1: Attacker | D1: Modifier | E1: Mil. Tac. | F1: Fort lvl | G1: Siege | H1: Exp | I1: Roll | K1: Attacker Damage | N1: Real Stats | O1: Mil. Tac. | P1: Exp | R1: Roll | S1: Casualties
A2: Frontline Unit | D2: 1 | E2: 1.5 | F2: 0 | G2: 5 | H2: 30 | I2: 5 | K2: Frontline | L2: Backline | N2: Frontline Attack | O2: =IF(E2=0,1,E2+1.5) -> 3 | P2: =H2/100 -> 0.3 | R2: 0 | S2: 36
A3: Attack | B3: Discipline | K3: =3000/3000*VLOOKUP(MAX(D2+I2,0),R2:S23,2,TRUE())*N3/10/(O10+IF(F10=0,0,(F10-G2)/10)/(1+P10)) -> 224.25 | L3: =3000/3000*VLOOKUP(MAX(D2+I2,0),R2:S23,2,TRUE())*N6/10/(O10+IF(F10=0,0,(F10-G2)/10)/(1+P10)) -> 401.45625 | N3: =A4+10 -> 46 | R3: 1 | S3: 48
A4: 36 | B4: 1 | K4: =K3+L3 -> 625.70625 | R4: 2 | S4: 60
A5: Backline Unit | N5: Backline Attack | R5: 3 | S5: 72
A6: Attack | B6: Support | C6: Discipline | N6: =(A7+10)*B7 -> 82.35 | R6: 4 | S6: 96
A7: 8.3 | B7: 4.5 | C7: 1 | K7: =K4/K12 -> 0.56676291 | R7: 5 | S7: 120
R8: 6 | S8: 150
A9: Defender | D9: Modifier | E9: Mil. Tac. | F9: Fort lvl | G9: Siege | H9: Exp | I9: Roll | K9: Defender Damage | N9: Real Stats | O9: Mil. Tac. | P9: Exp | R9: 7 | S9: 180
A10: Frontline Unit | D10: 2 | E10: 1.5 | F10: 6 | G10: 0 | H10: 30 | I10: 5 | K10: Frontline | L10: Backline | N10: Frontline Defence | O10: =IF(E10=0,1,E10+1.5) -> 3 | P10: =H10/100 -> 0.3 | R10: 8 | S10: 210
A11: Defence | B11: Discipline | K11: =3000/3000*VLOOKUP(MAX(D10+I10,0),R2:S23,2,TRUE())*N11/10/(O2+IF(F2=0,0,(F2-G10)/10)/(1+P2)) -> 204 | L11: =3000/3000*VLOOKUP(MAX(D10+I10,0),R2:S23,2,TRUE())*N14/10/(O2+IF(F2=0,0,(F2-G10)/10)/(1+P2)) -> 900 | N11: =A12+10 -> 34 | R11: 9 | S11: 240
A12: 24 | B12: 1 | K12: =K11+L11 -> 1104 | R12: 10 | S12: 270
A13: Backline Unit | N13: Backline Defence | R13: 11 | S13: 300
A14: Defence | B14: Support | C14: Discipline | N14: =(A15+10)*B15 -> 150 | R14: 12 | S14: 330
A15: 15 | B15: 6 | C15: 0.1 | K15: =K12/K4 -> 1.7644062 | R15: 13 | S15: 360
R16: 14 | S16: 390
J17: 0 | K17: 216 | L17: 216 | R17: 15 | S17: 420
J18: 1 | K18: 309 | L18: 422 | R18: 16 | S18: 450
J19: 2 | R19: 17 | S19: 480
J20: 3 | R20: 18 | S20: 510
J21: 4 | K21: 399 | L21: 540 | R21: 19 | S21: 540
J22: 5 | K22: 463 | L22: 753 | R22: 20 | S22: 570
J23: 6 | K23: 626 | L23: 1104 | R23: 21 | S23: 600

Sheet Navy
A1: Attacker | T1: Dice | U1: Modifier | W1: Date
A2: Dice | B2: Attack | C2: Hull | D2: Experience | E2: Evasion | F2: Strength | H2: Attack | I2: Org Damage | J2: Str Damage | T2: -5 | U2: 2 | W2: Base Stats
A3: 7 | B3: 17 | C3: 13 | D3: 0 | E3: 0 | F3: 1 | H3: =B3*VLOOKUP(A3,$T$2:$U$21,2)/C6*(1-(D6/100))*(1-E6)*F3 -> 46.363636 | I3: =H3*0.4 -> 18.545455 | J3: =H3*0.2 -> 9.2727273 | T3: -4 | U3: 2 | W3: No reforms
A4: Defender | T4: -3 | U4: 2 | W4: Unciv Reforms
A5: Dice | B5: Attack | C5: Hull | D5: Experience | E5: Evasion | F5: Strength | H5: Attack | I5: Org Damage | J5: Str Damage | T5: -2 | U5: 2 | W5: Base Techs
A6: 7 | B6: 25 | C6: 11 | D6: 0 | E6: 0 | F6: 1 | H6: =B6*VLOOKUP(A6,$T$2:$U$21,2)/C3*(1-(D3/100))*(1-E3)*F6 -> 57.692308 | I6: =H6*0.4 -> 23.076923 | J6: =H6*0.2 -> 11.538462 | T6: -1 | U6: 4 | W6: 2 row
T7: 0 | U7: 6
T8: 1 | U8: 8
T9: 2 | U9: 10
T10: 3 | U10: 12
T11: 4 | U11: 16
T12: 5 | U12: 20
T13: 6 | U13: 25
T14: 7 | U14: 30
T15: 8 | U15: 35
T16: 9 | U16: 40
T17: 10 | U17: 45
T18: 11 | U18: 50
... T21: 14 | U21: 80

Sheet Stocks
